Workbook

Sheet امتیاز دهی خبرگان
C1: 1 | D1: 2 | E1: 3 | F1: 4 | G1: 5 | H1: 6 | I1: 7 | J1: 8 | K1: 9 | L1: 10 | M1: 11 | N1: 12 | O1: AVERAGE | P1: Number of respondents
B3: 1 | C3: 4 | D3: 3 | E3: 3 | F3: 5 | G3: 4 | H3: 4 | I3: 5 | J3: 4 | K3: 4 | L3: 4 | M3: 4 | N3: 5 | O3: =AVERAGE(C3:N3) -> 4.0833333 | P3: =COUNT(C3:N3) -> 12
B4: 2 | C4: 4 | D4: 4 | E4: 4 | F4: 5 | G4: 5 | H4: 4 | I4: 5 | J4: 4 | K4: 3 | L4: 4 | M4: 4 | N4: 4 | O4: =AVERAGE(C4:N4) -> 4.1666667
B5: 3 | C5: 5 | D5: 4 | E5: 5 | F5: 3 | G5: 5 | H5: 3 | I5: 5 | J5: 5 | K5: 5 | L5: 5 | M5: 5 | N5: 5 | O5: =AVERAGE(C5:N5) -> 4.5833333
B6: 4 | C6: 4 | D6: 4 | E6: 4 | F6: 3 | G6: 4 | H6: 5 | I6: 3 | J6: 4 | K6: 5 | L6: 5 | M6: 4 | N6: 4 | O6: =AVERAGE(C6:N6) -> 4.0833333
B7: 5 | C7: 5 | D7: 2 | E7: 3 | F7: 5 | G7: 5 | H7: 4 | I7: 5 | J7: 4 | K7: 4 | L7: 4 | M7: 4 | N7: 5 | O7: =AVERAGE(C7:N7) -> 4.1666667
B8: 6 | C8: 5 | D8: 3 | E8: 4 | F8: 5 | G8: 4 | H8: 3 | I8: 4 | J8: 4 | K8: 4 | L8: 4 | M8: 4 | N8: 5 | O8: =AVERAGE(C8:N8) -> 4.0833333
B9: 7 | C9: 4 | D9: 4 | E9: 4 | F9: 5 | G9: 4 | H9: 4 | I9: 4 | J9: 4 | K9: 3 | L9: 4 | M9: 4 | N9: 4 | O9: =AVERAGE(C9:N9) -> 4
B10: 8 | C10: 5 | D10: 3 | E10: 3 | F10: 3 | G10: 5 | H10: 3 | I10: 5 | J10: 5 | K10: 5 | L10: 5 | M10: 4 | N10: 5 | O10: =AVERAGE(C10:N10) -> 4.25
B11: 9 | C11: 5 | D11: 3 | E11: 5 | F11: 4 | G11: 5 | H11: 4 | I11: 5 | J11: 4 | K11: 5 | L11: 5 | M11: 4 | N11: 4 | O11: =AVERAGE(C11:N11) -> 4.4166667
B12: 10 | C12: 4 | D12: 3 | E12: 5 | F12: 4 | G12: 4 | H12: 4 | I12: 4 | J12: 4 | K12: 4 | L12: 4 | M12: 4 | N12: 4 | O12: =AVERAGE(C12:N12) -> 4
B13: 11 | C13: 5 | D13: 3 | E13: 1 | F13: 5 | G13: 5 | H13: 2 | I13: 3 | J13: 5 | K13: 5 | L13: 5 | M13: 5 | N13: 5 | O13: =AVERAGE(C13:N13) -> 4.0833333
B14: 12 | C14: 5 | D14: 4 | E14: 3 | F14: 5 | G14: 5 | H14: 3 | I14: 3 | J14: 5 | K14: 5 | L14: 5 | M14: 4 | N14: 5 | O14: =AVERAGE(C14:N14) -> 4.3333333
B15: 13 | C15: 5 | D15: 3 | E15: 4 | F15: 5 | G15: 5 | H15: 3 | I15: 3 | J15: 4 | K15: 4 | L15: 4 | M15: 4 | N15: 5 | O15: =AVERAGE(C15:N15) -> 4.0833333
... B63: 61 | C63: 5 | D63: 4 | E63: 5 | F63: 4 | G63: 2 | H63: 3 | I63: 5 | J63: 5 | K63: 4 | L63: 5 | M63: 4 | N63: 5 | O63: =AVERAGE(C63:N63) -> 4.25
B64: 61* | C64: 5 | D64: 4 | E64: 5 | F64: 3 | G64: 5 | H64: 4 | I64: 4 | J64: 4 | K64: 4 | L64: 4 | M64: 4 | N64: 4 | O64: =AVERAGE(C64:N64) -> 4.1666667
B65: 62 | C65: 5 | D65: 3 | E65: 5 | F65: 3 | G65: 5 | H65: 4 | I65: 4 | J65: 4 | K65: 4 | L65: 4 | M65: 4 | N65: 4 | O65: =AVERAGE(C65:N65) -> 4.0833333
B66: 63 | C66: 4 | D66: 3 | E66: 5 | F66: 2 | G66: 3 | H66: 2 | I66: 5 | J66: 4 | K66: 5 | L66: 5 | M66: 5 | N66: 5 | O66: =AVERAGE(C66:N66) -> 4
B67: 64 | C67: 5 | D67: 2 | E67: 5 | F67: 5 | G67: 3 | H67: 4 | I67: 4 | J67: 4 | K67: 5 | L67: 5 | M67: 4 | N67: 4 | O67: =AVERAGE(C67:N67) -> 4.1666667
B68: 65 | C68: 5 | D68: 4 | E68: 5 | F68: 5 | G68: 4 | H68: 3 | I68: 5 | J68: 3 | K68: 4 | L68: 4 | M68: 3 | N68: 4 | O68: =AVERAGE(C68:N68) -> 4.0833333
B69: 66 | C69: 5 | D69: 2 | E69: 5 | F69: 5 | G69: 4 | H69: 3 | I69: 5 | J69: 4 | K69: 5 | L69: 4 | M69: 4 | N69: 4 | O69: =AVERAGE(C69:N69) -> 4.1666667
B70: 67 | C70: 5 | D70: 3 | E70: 5 | F70: 5 | G70: 2 | H70: 3 | I70: 5 | J70: 4 | K70: 5 | L70: 3 | M70: 4 | N70: 5 | O70: =AVERAGE(C70:N70) -> 4.0833333
B71: 68 | C71: 5 | D71: 3 | E71: 4 | F71: 5 | G71: 4 | H71: 4 | I71: 5 | J71: 3 | K71: 4 | L71: 3 | M71: 4 | N71: 5 | O71: =AVERAGE(C71:N71) -> 4.0833333
B72: 68* | C72: 5 | D72: 3 | E72: 2 | F72: 5 | G72: 3 | H72: 1 | I72: 4 | J72: 3 | K72: 5 | L72: 2 | M72: 3 | N72: 5 | O72: =AVERAGE(C72:N72) -> 3.4166667
B73: 69 | C73: 5 | D73: 3 | E73: 5 | F73: 5 | G73: 4 | H73: 3 | I73: 5 | J73: 3 | K73: 4 | L73: 4 | M73: 4 | N73: 4 | O73: =AVERAGE(C73:N73) -> 4.0833333
B74: 70 | C74: 5 | D74: 4 | E74: 1 | F74: 5 | G74: 2 | H74: 5 | I74: 5 | J74: 5 | K74: 5 | L74: 5 | M74: 4 | N74: 4 | O74: =AVERAGE(C74:N74) -> 4.1666667
B75: 71 | C75: 5 | D75: 3 | E75: 1 | F75: 5 | G75: 2 | H75: 4 | I75: 3 | J75: 3 | K75: 5 | L75: 1 | M75: 4 | N75: 5 | O75: =AVERAGE(C75:N75) -> 3.4166667
B76: 72 | C76: 4 | D76: 3 | E76: 1 | F76: 3 | G76: 3 | H76: 3 | I76: 4 | J76: 4 | K76: 4 | L76: 2 | M76: 5 | N76: 4 | O76: =AVERAGE(C76:N76) -> 3.3333333
B77: 73 | C77: 5 | D77: 3 | E77: 4 | F77: 3 | G77: 3 | H77: 4 | I77: 5 | J77: 4 | K77: 5 | L77: 5 | M77: 4 | N77: 4 | O77: =AVERAGE(C77:N77) -> 4.0833333
B78: 74 | C78: 5 | D78: 4 | E78: 4 | F78: 4 | G78: 3 | H78: 4 | I78: 4 | J78: 4 | K78: 5 | L78: 4 | M78: 4 | N78: 5 | O78: =AVERAGE(C78:N78) -> 4.1666667
B79: 75 | C79: 5 | D79: 4 | E79: 5 | F79: 5 | G79: 2 | H79: 3 | I79: 4 | J79: 4 | K79: 5 | L79: 4 | M79: 4 | N79: 4 | O79: =AVERAGE(C79:N79) -> 4.0833333
B80: 76 | C80: 4 | D80: 4 | E80: 4 | F80: 5 | G80: 4 | H80: 3 | I80: 5 | J80: 4 | K80: 4 | L80: 4 | M80: 4 | N80: 5 | O80: =AVERAGE(C80:N80) -> 4.1666667
B81: 77 | C81: 5 | D81: 4 | E81: 3 | F81: 5 | G81: 2 | H81: 2 | I81: 4 | J81: 5 | K81: 5 | L81: 5 | M81: 4 | N81: 4 | O81: =AVERAGE(C81:N81) -> 4
B82: 78 | C82: 5 | D82: 4 | E82: 3 | F82: 5 | G82: 4 | H82: 4 | I82: 4 | J82: 4 | K82: 5 | L82: 4 | M82: 4 | N82: 4 | O82: =AVERAGE(C82:N82) -> 4.1666667
B83: 79 | C83: 5 | D83: 4 | E83: 3 | F83: 4 | G83: 2 | H83: 5 | I83: 5 | J83: 3 | K83: 5 | L83: 5 | M83: 3 | N83: 5 | O83: =AVERAGE(C83:N83) -> 4.0833333
B84: 80 | C84: 5 | D84: 4 | E84: 3 | F84: 4 | G84: 3 | H84: 3 | I84: 4 | J84: 4 | K84: 5 | L84: 5 | M84: 4 | N84: 4 | O84: =AVERAGE(C84:N84) -> 4
... B124: 120 | C124: 5 | D124: 3 | E124: 5 | F124: 4 | G124: 5 | H124: 4 | I124: 4 | J124: 5 | K124: 5 | L124: 5 | M124: 3 | N124: 4 | O124: =AVERAGE(C124:N124) -> 4.3333333

Sheet عملیات فازی
C1: 1 | F1: 2 | I1: 3 | L1: 4 | O1: 5 | R1: 6 | U1: 7 | X1: 8 | AA1: 9 | AD1: 10 | AG1: 11 | AJ1: 12 | AM1: Average l,MU | AP1: Total Average | AS1: Defuzzification | AT1: Pass/Not Pass | AU1: Count Pass
C2: L | D2: M | E2: U | F2: L | G2: M | H2: U | I2: L | J2: M | K2: U | L2: L | M2: M | N2: U | O2: L | P2: M | Q2: U | R2: L | S2: M | T2: U | U2: L | V2: M | W2: U | X2: L | Y2: M | Z2: U | AA2: L | AB2: M | AC2: U | AD2: L | AE2: M | AF2: U | AG2: L | AH2: M | AI2: U | AJ2: L | AK2: M | AL2: U | AM2: L | AN2: M | AO2: U | AP2: L | AQ2: M | AR2: U | AS2: Final score | AT2: ≥ 0.7 | AU2: =COUNTIF(AT3:AT75,"Pass") -> 60
B3: 1 | C3: =IF('امتیاز دهی خبرگان'!$C3=0,0,IF('امتیاز دهی خبرگان'!$C3=1,'طیف فازی'!$B$2,IF('امتیاز دهی خبرگان'!$C3=2,'طیف فازی'!$B$3,IF('امتیاز دهی خبرگان'!$C3=3,'طیف فازی'!$B$4,IF('امتیاز دهی خبرگان'!$C3=4,'طیف فازی'!$B$5,'طیف فازی'!$B$6))))) -> 0.5 | D3: =IF('امتیاز دهی خبرگان'!$C3=0,0,IF('امتیاز دهی خبرگان'!$C3=1,'طیف فازی'!$C$2,IF('امتیاز دهی خبرگان'!$C3=2,'طیف فازی'!$C$3,IF('امتیاز دهی خبرگان'!$C3=3,'طیف فازی'!$C$4,IF('امتیاز دهی خبرگان'!$C3=4,'طیف فازی'!$C$5,'طیف فازی'!$C$6))))) -> 0.75 | E3: =IF('امتیاز دهی خبرگان'!$C3=0,0,IF('امتیاز دهی خبرگان'!$C3=1,'طیف فازی'!$D$2,IF('امتیاز دهی خبرگان'!$C3=2,'طیف فازی'!$D$3,IF('امتیاز دهی خبرگان'!$C3=3,'طیف فازی'!$D$4,IF('امتیاز دهی خبرگان'!$C3=4,'طیف فازی'!$D$5,'طیف فازی'!$D$6))))) -> 1 | F3: =IF('امتیاز دهی خبرگان'!$D3=0,0,IF('امتیاز دهی خبرگان'!$D3=1,'طیف فازی'!$B$2,IF('امتیاز دهی خبرگان'!$D3=2,'طیف فازی'!$B$3,IF('امتیاز دهی خبرگان'!$D3=3,'طیف فازی'!$B$4,IF('امتیاز دهی خبرگان'!$D3=4,'طیف فازی'!$B$5,'طیف فازی'!$B$6))))) -> 0.25 | G3: =IF('امتیاز دهی خبرگان'!$D3=0,0,IF('امتیاز دهی خبرگان'!$D3=1,'طیف فازی'!$D$2,IF('امتیاز دهی خبرگان'!$D3=2,'طیف فازی'!$C$3,IF('امتیاز دهی خبرگان'!$D3=3,'طیف فازی'!$C$4,IF('امتیاز دهی خبرگان'!$D3=4,'طیف فازی'!$C$5,'طیف فازی'!$C$6))))) -> 0.5 | H3: =IF('امتیاز دهی خبرگان'!$D3=0,0,IF('امتیاز دهی خبرگان'!$D3=1,'طیف فازی'!$D$2,IF('امتیاز دهی خبرگان'!$D3=2,'طیف فازی'!$D$3,IF('امتیاز دهی خبرگان'!$D3=3,'طیف فازی'!$D$4,IF('امتیاز دهی خبرگان'!$D3=4,'طیف فازی'!$D$5,'طیف فازی'!$D$6))))) -> 0.75 | I3: =IF('امتیاز دهی خبرگان'!$E3=0,0,IF('امتیاز دهی خبرگان'!$E3=1,'طیف فازی'!$B$2,IF('امتیاز دهی خبرگان'!$E3=2,'طیف فازی'!$B$3,IF('امتیاز دهی خبرگان'!$E3=3,'طیف فازی'!$B$4,IF('امتیاز دهی خبرگان'!$E3=4,'طیف فازی'!$B$5,'طیف فازی'!$B$6))))) -> 0.25 | J3: =IF('امتیاز دهی خبرگان'!$E3=0,0,IF('امتیاز دهی خبرگان'!$E3=1,'طیف فازی'!$C$2,IF('امتیاز دهی خبرگان'!$E3=2,'طیف فازی'!$C$3,IF('امتیاز دهی خبرگان'!$E3=3,'طیف فازی'!$C$4,IF('امتیاز دهی خبرگان'!$E3=4,'طیف فازی'!$C$5,'طیف فازی'!$C$6))))) -> 0.5 | K3: =IF('امتیاز دهی خبرگان'!$E3=0,0,IF('امتیاز دهی خبرگان'!$E3=1,'طیف فازی'!$D$2,IF('امتیاز دهی خبرگان'!$E3=2,'طیف فازی'!$D$3,IF('امتیاز دهی خبرگان'!$E3=3,'طیف فازی'!$D$4,IF('امتیاز دهی خبرگان'!$E3=4,'طیف فازی'!$D$5,'طیف فازی'!$D$6))))) -> 0.75 | L3: =IF('امتیاز دهی خبرگان'!$F3=0,0,IF('امتیاز دهی خبرگان'!$F3=1,'طیف فازی'!$B$2,IF('امتیاز دهی خبرگان'!$F3=2,'طیف فازی'!$B$3,IF('امتیاز دهی خبرگان'!$F3=3,'طیف فازی'!$B$4,IF('امتیاز دهی خبرگان'!$F3=4,'طیف فازی'!$B$5,'طیف فازی'!$B$6))))) -> 0.75 | M3: =IF('امتیاز دهی خبرگان'!$F3=0,0,IF('امتیاز دهی خبرگان'!$F3=1,'طیف فازی'!$C$2,IF('امتیاز دهی خبرگان'!$F3=2,'طیف فازی'!$C$3,IF('امتیاز دهی خبرگان'!$F3=3,'طیف فازی'!$C$4,IF('امتیاز دهی خبرگان'!$F3=4,'طیف فازی'!$C$5,'طیف فازی'!$C$6))))) -> 1 | N3: =IF('امتیاز دهی خبرگان'!$F3=0,0,IF('امتیاز دهی خبرگان'!$F3=1,'طیف فازی'!$D$2,IF('امتیاز دهی خبرگان'!$F3=2,'طیف فازی'!$D$3,IF('امتیاز دهی خبرگان'!$F3=3,'طیف فازی'!$D$4,IF('امتیاز دهی خبرگان'!$F3=4,'طیف فازی'!$D$5,'طیف فازی'!$D$6))))) -> 1 | O3: =IF('امتیاز دهی خبرگان'!$G3=0,0,IF('امتیاز دهی خبرگان'!$G3=1,'طیف فازی'!$B$2,IF('امتیاز دهی خبرگان'!$G3=2,'طیف فازی'!$B$3,IF('امتیاز دهی خبرگان'!$G3=3,'طیف فازی'!$B$4,IF('امتیاز دهی خبرگان'!$G3=4,'طیف فازی'!$B$5,'طیف فازی'!$B$6))))) -> 0.5 | P3: =IF('امتیاز دهی خبرگان'!$G3=0,0,IF('امتیاز دهی خبرگان'!$G3=1,'طیف فازی'!$C$2,IF('امتیاز دهی خبرگان'!$G3=2,'طیف فازی'!$C$3,IF('امتیاز دهی خبرگان'!$G3=3,'طیف فازی'!$C$4,IF('امتیاز دهی خبرگان'!$G3=4,'طیف فازی'!$C$5,'طیف فازی'!$C$6))))) -> 0.75 | Q3: =IF('امتیاز دهی خبرگان'!$G3=0,0,IF('امتیاز دهی خبرگان'!$G3=1,'طیف فازی'!$D$2,IF('امتیاز دهی خبرگان'!$G3=2,'طیف فازی'!$D$3,IF('امتیاز دهی خبرگان'!$G3=3,'طیف فازی'!$D$4,IF('امتیاز دهی خبرگان'!$G3=4,'طیف فازی'!$D$5,'طیف فازی'!$D$6))))) -> 1 | R3: =IF('امتیاز دهی خبرگان'!$H3=0,0,IF('امتیاز دهی خبرگان'!$H3=1,'طیف فازی'!$B$2,IF('امتیاز دهی خبرگان'!$H3=2,'طیف فازی'!$B$3,IF('امتیاز دهی خبرگان'!$H3=3,'طیف فازی'!$B$4,IF('امتیاز دهی خبرگان'!$H3=4,'طیف فازی'!$B$5,'طیف فازی'!$B$6))))) -> 0.5 | S3: =IF('امتیاز دهی خبرگان'!$H3=0,0,IF('امتیاز دهی خبرگان'!$H3=1,'طیف فازی'!$C$2,IF('امتیاز دهی خبرگان'!$H3=2,'طیف فازی'!$C$3,IF('امتیاز دهی خبرگان'!$H3=3,'طیف فازی'!$C$4,IF('امتیاز دهی خبرگان'!$H3=4,'طیف فازی'!$C$5,'طیف فازی'!$C$6))))) -> 0.75 | T3: =IF('امتیاز دهی خبرگان'!$H3=0,0,IF('امتیاز دهی خبرگان'!$H3=1,'طیف فازی'!$D$2,IF('امتیاز دهی خبرگان'!$H3=2,'طیف فازی'!$D$3,IF('امتیاز دهی خبرگان'!$H3=3,'طیف فازی'!$D$4,IF('امتیاز دهی خبرگان'!$H3=4,'طیف فازی'!$D$5,'طیف فازی'!$D$6))))) -> 1 | U3: =IF('امتیاز دهی خبرگان'!$I3=0,0,IF('امتیاز دهی خبرگان'!$I3=1,'طیف فازی'!$B$2,IF('امتیاز دهی خبرگان'!$I3=2,'طیف فازی'!$B$3,IF('امتیاز دهی خبرگان'!$I3=3,'طیف فازی'!$B$4,IF('امتیاز دهی خبرگان'!$I3=4,'طیف فازی'!$B$5,'طیف فازی'!$B$6))))) -> 0.75 | V3: =IF('امتیاز دهی خبرگان'!$I3=0,0,IF('امتیاز دهی خبرگان'!$I3=1,'طیف فازی'!$C$2,IF('امتیاز دهی خبرگان'!$I3=2,'طیف فازی'!$C$3,IF('امتیاز دهی خبرگان'!$I3=3,'طیف فازی'!$C$4,IF('امتیاز دهی خبرگان'!$I3=4,'طیف فازی'!$C$5,'طیف فازی'!$C$6))))) -> 1 | W3: =IF('امتیاز دهی خبرگان'!$I3=0,0,IF('امتیاز دهی خبرگان'!$I3=1,'طیف فازی'!$D$2,IF('امتیاز دهی خبرگان'!$I3=2,'طیف فازی'!$D$3,IF('امتیاز دهی خبرگان'!$I3=3,'طیف فازی'!$D$4,IF('امتیاز دهی خبرگان'!$I3=4,'طیف فازی'!$D$5,'طیف فازی'!$D$6))))) -> 1 | X3: =IF('امتیاز دهی خبرگان'!$J3=0,0,IF('امتیاز دهی خبرگان'!$J3=1,'طیف فازی'!$B$2,IF('امتیاز دهی خبرگان'!$J3=2,'طیف فازی'!$B$3,IF('امتیاز دهی خبرگان'!$J3=3,'طیف فازی'!$B$4,IF('امتیاز دهی خبرگان'!$J3=4,'طیف فازی'!$B$5,'طیف فازی'!$B$6))))) -> 0.5 | Y3: =IF('امتیاز دهی خبرگان'!$J3=0,0,IF('امتیاز دهی خبرگان'!$J3=1,'طیف فازی'!$C$2,IF('امتیاز دهی خبرگان'!$J3=2,'طیف فازی'!$C$3,IF('امتیاز دهی خبرگان'!$J3=3,'طیف فازی'!$C$4,IF('امتیاز دهی خبرگان'!$J3=4,'طیف فازی'!$C$5,'طیف فازی'!$C$6))))) -> 0.75 | Z3: =IF('امتیاز دهی خبرگان'!$J3=0,0,IF('امتیاز دهی خبرگان'!$J3=1,'طیف فازی'!$D$2,IF('امتیاز دهی خبرگان'!$J3=2,'طیف فازی'!$D$3,IF('امتیاز دهی خبرگان'!$J3=3,'طیف فازی'!$D$4,IF('امتیاز دهی خبرگان'!$J3=4,'طیف فازی'!$D$5,'طیف فازی'!$D$6))))) -> 1 | AA3: =IF('امتیاز دهی خبرگان'!$K3=0,0,IF('امتیاز دهی خبرگان'!$K3=1,'طیف فازی'!$B$2,IF('امتیاز دهی خبرگان'!$K3=2,'طیف فازی'!$B$3,IF('امتیاز دهی خبرگان'!$K3=3,'طیف فازی'!$B$4,IF('امتیاز دهی خبرگان'!$K3=4,'طیف فازی'!$B$5,'طیف فازی'!$B$6))))) -> 0.5 | AB3: =IF('امتیاز دهی خبرگان'!$K3=0,0,IF('امتیاز دهی خبرگان'!$K3=1,'طیف فازی'!$C$2,IF('امتیاز دهی خبرگان'!$K3=2,'طیف فازی'!$C$3,IF('امتیاز دهی خبرگان'!$K3=3,'طیف فازی'!$C$4,IF('امتیاز دهی خبرگان'!$K3=4,'طیف فازی'!$C$5,'طیف فازی'!$C$6))))) -> 0.75 | AC3: =IF('امتیاز دهی خبرگان'!$K3=0,0,IF('امتیاز دهی خبرگان'!$K3=1,'طیف فازی'!$D$2,IF('امتیاز دهی خبرگان'!$K3=2,'طیف فازی'!$D$3,IF('امتیاز دهی خبرگان'!$K3=3,'طیف فازی'!$D$4,IF('امتیاز دهی خبرگان'!$K3=4,'طیف فازی'!$D$5,'طیف فازی'!$D$6))))) -> 1 | AD3: =IF('امتیاز دهی خبرگان'!$L3=0,0,IF('امتیاز دهی خبرگان'!$L3=1,'طیف فازی'!$B$2,IF('امتیاز دهی خبرگان'!$L3=2,'طیف فازی'!$B$3,IF('امتیاز دهی خبرگان'!$L3=3,'طیف فازی'!$B$4,IF('امتیاز دهی خبرگان'!$L3=4,'طیف فازی'!$B$5,'طیف فازی'!$B$6))))) -> 0.5 | AE3: =IF('امتیاز دهی خبرگان'!$L3=0,0,IF('امتیاز دهی خبرگان'!$L3=1,'طیف فازی'!$C$2,IF('امتیاز دهی خبرگان'!$L3=2,'طیف فازی'!$C$3,IF('امتیاز دهی خبرگان'!$L3=3,'طیف فازی'!$C$4,IF('امتیاز دهی خبرگان'!$L3=4,'طیف فازی'!$C$5,'طیف فازی'!$C$6))))) -> 0.75 | AF3: =IF('امتیاز دهی خبرگان'!$L3=0,0,IF('امتیاز دهی خبرگان'!$L3=1,'طیف فازی'!$D$2,IF('امتیاز دهی خبرگان'!$L3=2,'طیف فازی'!$D$3,IF('امتیاز دهی خبرگان'!$L3=3,'طیف فازی'!$D$4,IF('امتیاز دهی خبرگان'!$L3=4,'طیف فازی'!$D$5,'طیف فازی'!$D$6))))) -> 1 | AG3: =IF('امتیاز دهی خبرگان'!$M3=0,0,IF('امتیاز دهی خبرگان'!$M3=1,'طیف فازی'!$B$2,IF('امتیاز دهی خبرگان'!$M3=2,'طیف فازی'!$B$3,IF('امتیاز دهی خبرگان'!$M3=3,'طیف فازی'!$B$4,IF('امتیاز دهی خبرگان'!$M3=4,'طیف فازی'!$B$5,'طیف فازی'!$B$6))))) -> 0.5 | AH3: =IF('امتیاز دهی خبرگان'!$M3=0,0,IF('امتیاز دهی خبرگان'!$M3=1,'طیف فازی'!$C$2,IF('امتیاز دهی خبرگان'!$M3=2,'طیف فازی'!$C$3,IF('امتیاز دهی خبرگان'!$M3=3,'طیف فازی'!$C$4,IF('امتیاز دهی خبرگان'!$M3=4,'طیف فازی'!$C$5,'طیف فازی'!$C$6))))) -> 0.75 | AI3: =IF('امتیاز دهی خبرگان'!$M3=0,0,IF('امتیاز دهی خبرگان'!$M3=1,'طیف فازی'!$D$2,IF('امتیاز دهی خبرگان'!$M3=2,'طیف فازی'!$D$3,IF('امتیاز دهی خبرگان'!$M3=3,'طیف فازی'!$D$4,IF('امتیاز دهی خبرگان'!$M3=4,'طیف فازی'!$D$5,'طیف فازی'!$D$6))))) -> 1 | AJ3: =IF('امتیاز دهی خبرگان'!$N3=0,0,IF('امتیاز دهی خبرگان'!$N3=1,'طیف فازی'!$B$2,IF('امتیاز دهی خبرگان'!$N3=2,'طیف فازی'!$B$3,IF('امتیاز دهی خبرگان'!$N3=3,'طیف فازی'!$B$4,IF('امتیاز دهی خبرگان'!$N3=4,'طیف فازی'!$B$5,'طیف فازی'!$B$6))))) -> 0.75 | AK3: =IF('امتیاز دهی خبرگان'!$N3=0,0,IF('امتیاز دهی خبرگان'!$N3=1,'طیف فازی'!$C$2,IF('امتیاز دهی خبرگان'!$N3=2,'طیف فازی'!$C$3,IF('امتیاز دهی خبرگان'!$N3=3,'طیف فازی'!$C$4,IF('امتیاز دهی خبرگان'!$N3=4,'طیف فازی'!$C$5,'طیف فازی'!$C$6))))) -> 1 | AL3: =IF('امتیاز دهی خبرگان'!$N3=0,0,IF('امتیاز دهی خبرگان'!$N3=1,'طیف فازی'!$D$2,IF('امتیاز دهی خبرگان'!$N3=2,'طیف فازی'!$D$3,IF('امتیاز دهی خبرگان'!$N3=3,'طیف فازی'!$D$4,IF('امتیاز دهی خبرگان'!$N3=4,'طیف فازی'!$D$5,'طیف فازی'!$D$6))))) -> 1 | AM3: =C3+F3+I3+L3+O3+R3+U3+X3+AA3+AD3+AG3+AJ3 -> 6.25 | AN3: =D3+G3+J3+M3+P3+S3+V3+Y3+AB3+AE3+AH3+AK3 -> 9.25 | AO3: =E3+H3+K3+N3+Q3+T3+W3+Z3+AC3+AF3+AI3+AL3 -> 11.5 | AP3: =(AM3)/$AU$4 -> 0.52083333 | AQ3: =(AN3)/$AU$4 -> 0.77083333 | AR3: =(AO3)/$AU$4 -> 0.95833333 | AS3: =AVERAGE(AP3:AR3) -> 0.75 | AT3: =IF(AS3>=0.7,"Pass","Not Pass") -> Pass | AU3: Number of respondents
B4: 2 | C4: =IF('امتیاز دهی خبرگان'!$C4=0,0,IF('امتیاز دهی خبرگان'!$C4=1,'طیف فازی'!$B$2,IF('امتیاز دهی خبرگان'!$C4=2,'طیف فازی'!$B$3,IF('امتیاز دهی خبرگان'!$C4=3,'طیف فازی'!$B$4,IF('امتیاز دهی خبرگان'!$C4=4,'طیف فازی'!$B$5,'طیف فازی'!$B$6))))) -> 0.5 | D4: =IF('امتیاز دهی خبرگان'!$C4=0,0,IF('امتیاز دهی خبرگان'!$C4=1,'طیف فازی'!$C$2,IF('امتیاز دهی خبرگان'!$C4=2,'طیف فازی'!$C$3,IF('امتیاز دهی خبرگان'!$C4=3,'طیف فازی'!$C$4,IF('امتیاز دهی خبرگان'!$C4=4,'طیف فازی'!$C$5,'طیف فازی'!$C$6))))) -> 0.75 | E4: =IF('امتیاز دهی خبرگان'!$C4=0,0,IF('امتیاز دهی خبرگان'!$C4=1,'طیف فازی'!$D$2,IF('امتیاز دهی خبرگان'!$C4=2,'طیف فازی'!$D$3,IF('امتیاز دهی خبرگان'!$C4=3,'طیف فازی'!$D$4,IF('امتیاز دهی خبرگان'!$C4=4,'طیف فازی'!$D$5,'طیف فازی'!$D$6))))) -> 1 | F4: =IF('امتیاز دهی خبرگان'!$D4=0,0,IF('امتیاز دهی خبرگان'!$D4=1,'طیف فازی'!$B$2,IF('امتیاز دهی خبرگان'!$D4=2,'طیف فازی'!$B$3,IF('امتیاز دهی خبرگان'!$D4=3,'طیف فازی'!$B$4,IF('امتیاز دهی خبرگان'!$D4=4,'طیف فازی'!$B$5,'طیف فازی'!$B$6))))) -> 0.5 | G4: =IF('امتیاز دهی خبرگان'!$D4=0,0,IF('امتیاز دهی خبرگان'!$D4=1,'طیف فازی'!$D$2,IF('امتیاز دهی خبرگان'!$D4=2,'طیف فازی'!$C$3,IF('امتیاز دهی خبرگان'!$D4=3,'طیف فازی'!$C$4,IF('امتیاز دهی خبرگان'!$D4=4,'طیف فازی'!$C$5,'طیف فازی'!$C$6))))) -> 0.75 | H4: =IF('امتیاز دهی خبرگان'!$D4=0,0,IF('امتیاز دهی خبرگان'!$D4=1,'طیف فازی'!$D$2,IF('امتیاز دهی خبرگان'!$D4=2,'طیف فازی'!$D$3,IF('امتیاز دهی خبرگان'!$D4=3,'طیف فازی'!$D$4,IF('امتیاز دهی خبرگان'!$D4=4,'طیف فازی'!$D$5,'طیف فازی'!$D$6))))) -> 1 | I4: =IF('امتیاز دهی خبرگان'!$E4=0,0,IF('امتیاز دهی خبرگان'!$E4=1,'طیف فازی'!$B$2,IF('امتیاز دهی خبرگان'!$E4=2,'طیف فازی'!$B$3,IF('امتیاز دهی خبرگان'!$E4=3,'طیف فازی'!$B$4,IF('امتیاز دهی خبرگان'!$E4=4,'طیف فازی'!$B$5,'طیف فازی'!$B$6))))) -> 0.5 | J4: =IF('امتیاز دهی خبرگان'!$E4=0,0,IF('امتیاز دهی خبرگان'!$E4=1,'طیف فازی'!$C$2,IF('امتیاز دهی خبرگان'!$E4=2,'طیف فازی'!$C$3,IF('امتیاز دهی خبرگان'!$E4=3,'طیف فازی'!$C$4,IF('امتیاز دهی خبرگان'!$E4=4,'طیف فازی'!$C$5,'طیف فازی'!$C$6))))) -> 0.75 | K4: =IF('امتیاز دهی خبرگان'!$E4=0,0,IF('امتیاز دهی خبرگان'!$E4=1,'طیف فازی'!$D$2,IF('امتیاز دهی خبرگان'!$E4=2,'طیف فازی'!$D$3,IF('امتیاز دهی خبرگان'!$E4=3,'طیف فازی'!$D$4,IF('امتیاز دهی خبرگان'!$E4=4,'طیف فازی'!$D$5,'طیف فازی'!$D$6))))) -> 1 | L4: =IF('امتیاز دهی خبرگان'!$F4=0,0,IF('امتیاز دهی خبرگان'!$F4=1,'طیف فازی'!$B$2,IF('امتیاز دهی خبرگان'!$F4=2,'طیف فازی'!$B$3,IF('امتیاز دهی خبرگان'!$F4=3,'طیف فازی'!$B$4,IF('امتیاز دهی خبرگان'!$F4=4,'طیف فازی'!$B$5,'طیف فازی'!$B$6))))) -> 0.75 | M4: =IF('امتیاز دهی خبرگان'!$F4=0,0,IF('امتیاز دهی خبرگان'!$F4=1,'طیف فازی'!$C$2,IF('امتیاز دهی خبرگان'!$F4=2,'طیف فازی'!$C$3,IF('امتیاز دهی خبرگان'!$F4=3,'طیف فازی'!$C$4,IF('امتیاز دهی خبرگان'!$F4=4,'طیف فازی'!$C$5,'طیف فازی'!$C$6))))) -> 1 | N4: =IF('امتیاز دهی خبرگان'!$F4=0,0,IF('امتیاز دهی خبرگان'!$F4=1,'طیف فازی'!$D$2,IF('امتیاز دهی خبرگان'!$F4=2,'طیف فازی'!$D$3,IF('امتیاز دهی خبرگان'!$F4=3,'طیف فازی'!$D$4,IF('امتیاز دهی خبرگان'!$F4=4,'طیف فازی'!$D$5,'طیف فازی'!$D$6))))) -> 1 | O4: =IF('امتیاز دهی خبرگان'!$G4=0,0,IF('امتیاز دهی خبرگان'!$G4=1,'طیف فازی'!$B$2,IF('امتیاز دهی خبرگان'!$G4=2,'طیف فازی'!$B$3,IF('امتیاز دهی خبرگان'!$G4=3,'طیف فازی'!$B$4,IF('امتیاز دهی خبرگان'!$G4=4,'طیف فازی'!$B$5,'طیف فازی'!$B$6))))) -> 0.75 | P4: =IF('امتیاز دهی خبرگان'!$G4=0,0,IF('امتیاز دهی خبرگان'!$G4=1,'طیف فازی'!$C$2,IF('امتیاز دهی خبرگان'!$G4=2,'طیف فازی'!$C$3,IF('امتیاز دهی خبرگان'!$G4=3,'طیف فازی'!$C$4,IF('امتیاز دهی خبرگان'!$G4=4,'طیف فازی'!$C$5,'طیف فازی'!$C$6))))) -> 1 | Q4: =IF('امتیاز دهی خبرگان'!$G4=0,0,IF('امتیاز دهی خبرگان'!$G4=1,'طیف فازی'!$D$2,IF('امتیاز دهی خبرگان'!$G4=2,'طیف فازی'!$D$3,IF('امتیاز دهی خبرگان'!$G4=3,'طیف فازی'!$D$4,IF('امتیاز دهی خبرگان'!$G4=4,'طیف فازی'!$D$5,'طیف فازی'!$D$6))))) -> 1 | R4: =IF('امتیاز دهی خبرگان'!$H4=0,0,IF('امتیاز دهی خبرگان'!$H4=1,'طیف فازی'!$B$2,IF('امتیاز دهی خبرگان'!$H4=2,'طیف فازی'!$B$3,IF('امتیاز دهی خبرگان'!$H4=3,'طیف فازی'!$B$4,IF('امتیاز دهی خبرگان'!$H4=4,'طیف فازی'!$B$5,'طیف فازی'!$B$6))))) -> 0.5 | S4: =IF('امتیاز دهی خبرگان'!$H4=0,0,IF('امتیاز دهی خبرگان'!$H4=1,'طیف فازی'!$C$2,IF('امتیاز دهی خبرگان'!$H4=2,'طیف فازی'!$C$3,IF('امتیاز دهی خبرگان'!$H4=3,'طیف فازی'!$C$4,IF('امتیاز دهی خبرگان'!$H4=4,'طیف فازی'!$C$5,'طیف فازی'!$C$6))))) -> 0.75 | T4: =IF('امتیاز دهی خبرگان'!$H4=0,0,IF('امتیاز دهی خبرگان'!$H4=1,'طیف فازی'!$D$2,IF('امتیاز دهی خبرگان'!$H4=2,'طیف فازی'!$D$3,IF('امتیاز دهی خبرگان'!$H4=3,'طیف فازی'!$D$4,IF('امتیاز دهی خبرگان'!$H4=4,'طیف فازی'!$D$5,'طیف فازی'!$D$6))))) -> 1 | U4: =IF('امتیاز دهی خبرگان'!$I4=0,0,IF('امتیاز دهی خبرگان'!$I4=1,'طیف فازی'!$B$2,IF('امتیاز دهی خبرگان'!$I4=2,'طیف فازی'!$B$3,IF('امتیاز دهی خبرگان'!$I4=3,'طیف فازی'!$B$4,IF('امتیاز دهی خبرگان'!$I4=4,'طیف فازی'!$B$5,'طیف فازی'!$B$6))))) -> 0.75 | V4: =IF('امتیاز دهی خبرگان'!$I4=0,0,IF('امتیاز دهی خبرگان'!$I4=1,'طیف فازی'!$C$2,IF('امتیاز دهی خبرگان'!$I4=2,'طیف فازی'!$C$3,IF('امتیاز دهی خبرگان'!$I4=3,'طیف فازی'!$C$4,IF('امتیاز دهی خبرگان'!$I4=4,'طیف فازی'!$C$5,'طیف فازی'!$C$6))))) -> 1 | W4: =IF('امتیاز دهی خبرگان'!$I4=0,0,IF('امتیاز دهی خبرگان'!$I4=1,'طیف فازی'!$D$2,IF('امتیاز دهی خبرگان'!$I4=2,'طیف فازی'!$D$3,IF('امتیاز دهی خبرگان'!$I4=3,'طیف فازی'!$D$4,IF('امتیاز دهی خبرگان'!$I4=4,'طیف فازی'!$D$5,'طیف فازی'!$D$6))))) -> 1 | X4: =IF('امتیاز دهی خبرگان'!$J4=0,0,IF('امتیاز دهی خبرگان'!$J4=1,'طیف فازی'!$B$2,IF('امتیاز دهی خبرگان'!$J4=2,'طیف فازی'!$B$3,IF('امتیاز دهی خبرگان'!$J4=3,'طیف فازی'!$B$4,IF('امتیاز دهی خبرگان'!$J4=4,'طیف فازی'!$B$5,'طیف فازی'!$B$6))))) -> 0.5 | Y4: =IF('امتیاز دهی خبرگان'!$J4=0,0,IF('امتیاز دهی خبرگان'!$J4=1,'طیف فازی'!$C$2,IF('امتیاز دهی خبرگان'!$J4=2,'طیف فازی'!$C$3,IF('امتیاز دهی خبرگان'!$J4=3,'طیف فازی'!$C$4,IF('امتیاز دهی خبرگان'!$J4=4,'طیف فازی'!$C$5,'طیف فازی'!$C$6))))) -> 0.75 | Z4: =IF('امتیاز دهی خبرگان'!$J4=0,0,IF('امتیاز دهی خبرگان'!$J4=1,'طیف فازی'!$D$2,IF('امتیاز دهی خبرگان'!$J4=2,'طیف فازی'!$D$3,IF('امتیاز دهی خبرگان'!$J4=3,'طیف فازی'!$D$4,IF('امتیاز دهی خبرگان'!$J4=4,'طیف فازی'!$D$5,'طیف فازی'!$D$6))))) -> 1 | AA4: =IF('امتیاز دهی خبرگان'!$K4=0,0,IF('امتیاز دهی خبرگان'!$K4=1,'طیف فازی'!$B$2,IF('امتیاز دهی خبرگان'!$K4=2,'طیف فازی'!$B$3,IF('امتیاز دهی خبرگان'!$K4=3,'طیف فازی'!$B$4,IF('امتیاز دهی خبرگان'!$K4=4,'طیف فازی'!$B$5,'طیف فازی'!$B$6))))) -> 0.25 | AB4: =IF('امتیاز دهی خبرگان'!$K4=0,0,IF('امتیاز دهی خبرگان'!$K4=1,'طیف فازی'!$C$2,IF('امتیاز دهی خبرگان'!$K4=2,'طیف فازی'!$C$3,IF('امتیاز دهی خبرگان'!$K4=3,'طیف فازی'!$C$4,IF('امتیاز دهی خبرگان'!$K4=4,'طیف فازی'!$C$5,'طیف فازی'!$C$6))))) -> 0.5 | AC4: =IF('امتیاز دهی خبرگان'!$K4=0,0,IF('امتیاز دهی خبرگان'!$K4=1,'طیف فازی'!$D$2,IF('امتیاز دهی خبرگان'!$K4=2,'طیف فازی'!$D$3,IF('امتیاز دهی خبرگان'!$K4=3,'طیف فازی'!$D$4,IF('امتیاز دهی خبرگان'!$K4=4,'طیف فازی'!$D$5,'طیف فازی'!$D$6))))) -> 0.75 | AD4: =IF('امتیاز دهی خبرگان'!$L4=0,0,IF('امتیاز دهی خبرگان'!$L4=1,'طیف فازی'!$B$2,IF('امتیاز دهی خبرگان'!$L4=2,'طیف فازی'!$B$3,IF('امتیاز دهی خبرگان'!$L4=3,'طیف فازی'!$B$4,IF('امتیاز دهی خبرگان'!$L4=4,'طیف فازی'!$B$5,'طیف فازی'!$B$6))))) -> 0.5 | AE4: =IF('امتیاز دهی خبرگان'!$L4=0,0,IF('امتیاز دهی خبرگان'!$L4=1,'طیف فازی'!$C$2,IF('امتیاز دهی خبرگان'!$L4=2,'طیف فازی'!$C$3,IF('امتیاز دهی خبرگان'!$L4=3,'طیف فازی'!$C$4,IF('امتیاز دهی خبرگان'!$L4=4,'طیف فازی'!$C$5,'طیف فازی'!$C$6))))) -> 0.75 | AF4: =IF('امتیاز دهی خبرگان'!$L4=0,0,IF('امتیاز دهی خبرگان'!$L4=1,'طیف فازی'!$D$2,IF('امتیاز دهی خبرگان'!$L4=2,'طیف فازی'!$D$3,IF('امتیاز دهی خبرگان'!$L4=3,'طیف فازی'!$D$4,IF('امتیاز دهی خبرگان'!$L4=4,'طیف فازی'!$D$5,'طیف فازی'!$D$6))))) -> 1 | AG4: =IF('امتیاز دهی خبرگان'!$M4=0,0,IF('امتیاز دهی خبرگان'!$M4=1,'طیف فازی'!$B$2,IF('امتیاز دهی خبرگان'!$M4=2,'طیف فازی'!$B$3,IF('امتیاز دهی خبرگان'!$M4=3,'طیف فازی'!$B$4,IF('امتیاز دهی خبرگان'!$M4=4,'طیف فازی'!$B$5,'طیف فازی'!$B$6))))) -> 0.5 | AH4: =IF('امتیاز دهی خبرگان'!$M4=0,0,IF('امتیاز دهی خبرگان'!$M4=1,'طیف فازی'!$C$2,IF('امتیاز دهی خبرگان'!$M4=2,'طیف فازی'!$C$3,IF('امتیاز دهی خبرگان'!$M4=3,'طیف فازی'!$C$4,IF('امتیاز دهی خبرگان'!$M4=4,'طیف فازی'!$C$5,'طیف فازی'!$C$6))))) -> 0.75 | AI4: =IF('امتیاز دهی خبرگان'!$M4=0,0,IF('امتیاز دهی خبرگان'!$M4=1,'طیف فازی'!$D$2,IF('امتیاز دهی خبرگان'!$M4=2,'طیف فازی'!$D$3,IF('امتیاز دهی خبرگان'!$M4=3,'طیف فازی'!$D$4,IF('امتیاز دهی خبرگان'!$M4=4,'طیف فازی'!$D$5,'طیف فازی'!$D$6))))) -> 1 | AJ4: =IF('امتیاز دهی خبرگان'!$N4=0,0,IF('امتیاز دهی خبرگان'!$N4=1,'طیف فازی'!$B$2,IF('امتیاز دهی خبرگان'!$N4=2,'طیف فازی'!$B$3,IF('امتیاز دهی خبرگان'!$N4=3,'طیف فازی'!$B$4,IF('امتیاز دهی خبرگان'!$N4=4,'طیف فازی'!$B$5,'طیف فازی'!$B$6))))) -> 0.5 | AK4: =IF('امتیاز دهی خبرگان'!$N4=0,0,IF('امتیاز دهی خبرگان'!$N4=1,'طیف فازی'!$C$2,IF('امتیاز دهی خبرگان'!$N4=2,'طیف فازی'!$C$3,IF('امتیاز دهی خبرگان'!$N4=3,'طیف فازی'!$C$4,IF('امتیاز دهی خبرگان'!$N4=4,'طیف فازی'!$C$5,'طیف فازی'!$C$6))))) -> 0.75 | AL4: =IF('امتیاز دهی خبرگان'!$N4=0,0,IF('امتیاز دهی خبرگان'!$N4=1,'طیف فازی'!$D$2,IF('امتیاز دهی خبرگان'!$N4=2,'طیف فازی'!$D$3,IF('امتیاز دهی خبرگان'!$N4=3,'طیف فازی'!$D$4,IF('امتیاز دهی خبرگان'!$N4=4,'طیف فازی'!$D$5,'طیف فازی'!$D$6))))) -> 1 | AM4: =C4+F4+I4+L4+O4+R4+U4+X4+AA4+AD4+AG4+AJ4 -> 6.5 | AN4: =D4+G4+J4+M4+P4+S4+V4+Y4+AB4+AE4+AH4+AK4 -> 9.5 | AO4: =E4+H4+K4+N4+Q4+T4+W4+Z4+AC4+AF4+AI4+AL4 -> 11.75 | AP4: =(AM4)/$AU$4 -> 0.54166667 | AQ4: =(AN4)/$AU$4 -> 0.79166667 | AR4: =(AO4)/$AU$4 -> 0.97916667 | AS4: =AVERAGE(AP4:AR4) -> 0.77083333 | AT4: =IF(AS4>=0.7,"Pass","Not Pass") -> Pass | AU4: ='امتیاز دهی خبرگان'!P3 -> 12
B5: 3 | C5: =IF('امتیاز دهی خبرگان'!$C5=0,0,IF('امتیاز دهی خبرگان'!$C5=1,'طیف فازی'!$B$2,IF('امتیاز دهی خبرگان'!$C5=2,'طیف فازی'!$B$3,IF('امتیاز دهی خبرگان'!$C5=3,'طیف فازی'!$B$4,IF('امتیاز دهی خبرگان'!$C5=4,'طیف فازی'!$B$5,'طیف فازی'!$B$6))))) -> 0.75 | D5: =IF('امتیاز دهی خبرگان'!$C5=0,0,IF('امتیاز دهی خبرگان'!$C5=1,'طیف فازی'!$C$2,IF('امتیاز دهی خبرگان'!$C5=2,'طیف فازی'!$C$3,IF('امتیاز دهی خبرگان'!$C5=3,'طیف فازی'!$C$4,IF('امتیاز دهی خبرگان'!$C5=4,'طیف فازی'!$C$5,'طیف فازی'!$C$6))))) -> 1 | E5: =IF('امتیاز دهی خبرگان'!$C5=0,0,IF('امتیاز دهی خبرگان'!$C5=1,'طیف فازی'!$D$2,IF('امتیاز دهی خبرگان'!$C5=2,'طیف فازی'!$D$3,IF('امتیاز دهی خبرگان'!$C5=3,'طیف فازی'!$D$4,IF('امتیاز دهی خبرگان'!$C5=4,'طیف فازی'!$D$5,'طیف فازی'!$D$6))))) -> 1 | F5: =IF('امتیاز دهی خبرگان'!$D5=0,0,IF('امتیاز دهی خبرگان'!$D5=1,'طیف فازی'!$B$2,IF('امتیاز دهی خبرگان'!$D5=2,'طیف فازی'!$B$3,IF('امتیاز دهی خبرگان'!$D5=3,'طیف فازی'!$B$4,IF('امتیاز دهی خبرگان'!$D5=4,'طیف فازی'!$B$5,'طیف فازی'!$B$6))))) -> 0.5 | G5: =IF('امتیاز دهی خبرگان'!$D5=0,0,IF('امتیاز دهی خبرگان'!$D5=1,'طیف فازی'!$D$2,IF('امتیاز دهی خبرگان'!$D5=2,'طیف فازی'!$C$3,IF('امتیاز دهی خبرگان'!$D5=3,'طیف فازی'!$C$4,IF('امتیاز دهی خبرگان'!$D5=4,'طیف فازی'!$C$5,'طیف فازی'!$C$6))))) -> 0.75 | H5: =IF('امتیاز دهی خبرگان'!$D5=0,0,IF('امتیاز دهی خبرگان'!$D5=1,'طیف فازی'!$D$2,IF('امتیاز دهی خبرگان'!$D5=2,'طیف فازی'!$D$3,IF('امتیاز دهی خبرگان'!$D5=3,'طیف فازی'!$D$4,IF('امتیاز دهی خبرگان'!$D5=4,'طیف فازی'!$D$5,'طیف فازی'!$D$6))))) -> 1 | I5: =IF('امتیاز دهی خبرگان'!$E5=0,0,IF('امتیاز دهی خبرگان'!$E5=1,'طیف فازی'!$B$2,IF('امتیاز دهی خبرگان'!$E5=2,'طیف فازی'!$B$3,IF('امتیاز دهی خبرگان'!$E5=3,'طیف فازی'!$B$4,IF('امتیاز دهی خبرگان'!$E5=4,'طیف فازی'!$B$5,'طیف فازی'!$B$6))))) -> 0.75 | J5: =IF('امتیاز دهی خبرگان'!$E5=0,0,IF('امتیاز دهی خبرگان'!$E5=1,'طیف فازی'!$C$2,IF('امتیاز دهی خبرگان'!$E5=2,'طیف فازی'!$C$3,IF('امتیاز دهی خبرگان'!$E5=3,'طیف فازی'!$C$4,IF('امتیاز دهی خبرگان'!$E5=4,'طیف فازی'!$C$5,'طیف فازی'!$C$6))))) -> 1 | K5: =IF('امتیاز دهی خبرگان'!$E5=0,0,IF('امتیاز دهی خبرگان'!$E5=1,'طیف فازی'!$D$2,IF('امتیاز دهی خبرگان'!$E5=2,'طیف فازی'!$D$3,IF('امتیاز دهی خبرگان'!$E5=3,'طیف فازی'!$D$4,IF('امتیاز دهی خبرگان'!$E5=4,'طیف فازی'!$D$5,'طیف فازی'!$D$6))))) -> 1 | L5: =IF('امتیاز دهی خبرگان'!$F5=0,0,IF('امتیاز دهی خبرگان'!$F5=1,'طیف فازی'!$B$2,IF('امتیاز دهی خبرگان'!$F5=2,'طیف فازی'!$B$3,IF('امتیاز دهی خبرگان'!$F5=3,'طیف فازی'!$B$4,IF('امتیاز دهی خبرگان'!$F5=4,'طیف فازی'!$B$5,'طیف فازی'!$B$6))))) -> 0.25 | M5: =IF('امتیاز دهی خبرگان'!$F5=0,0,IF('امتیاز دهی خبرگان'!$F5=1,'طیف فازی'!$C$2,IF('امتیاز دهی خبرگان'!$F5=2,'طیف فازی'!$C$3,IF('امتیاز دهی خبرگان'!$F5=3,'طیف فازی'!$C$4,IF('امتیاز دهی خبرگان'!$F5=4,'طیف فازی'!$C$5,'طیف فازی'!$C$6))))) -> 0.5 | N5: =IF('امتیاز دهی خبرگان'!$F5=0,0,IF('امتیاز دهی خبرگان'!$F5=1,'طیف فازی'!$D$2,IF('امتیاز دهی خبرگان'!$F5=2,'طیف فازی'!$D$3,IF('امتیاز دهی خبرگان'!$F5=3,'طیف فازی'!$D$4,IF('امتیاز دهی خبرگان'!$F5=4,'طیف فازی'!$D$5,'طیف فازی'!$D$6))))) -> 0.75 | O5: =IF('امتیاز دهی خبرگان'!$G5=0,0,IF('امتیاز دهی خبرگان'!$G5=1,'طیف فازی'!$B$2,IF('امتیاز دهی خبرگان'!$G5=2,'طیف فازی'!$B$3,IF('امتیاز دهی خبرگان'!$G5=3,'طیف فازی'!$B$4,IF('امتیاز دهی خبرگان'!$G5=4,'طیف فازی'!$B$5,'طیف فازی'!$B$6))))) -> 0.75 | P5: =IF('امتیاز دهی خبرگان'!$G5=0,0,IF('امتیاز دهی خبرگان'!$G5=1,'طیف فازی'!$C$2,IF('امتیاز دهی خبرگان'!$G5=2,'طیف فازی'!$C$3,IF('امتیاز دهی خبرگان'!$G5=3,'طیف فازی'!$C$4,IF('امتیاز دهی خبرگان'!$G5=4,'طیف فازی'!$C$5,'طیف فازی'!$C$6))))) -> 1 | Q5: =IF('امتیاز دهی خبرگان'!$G5=0,0,IF('امتیاز دهی خبرگان'!$G5=1,'طیف فازی'!$D$2,IF('امتیاز دهی خبرگان'!$G5=2,'طیف فازی'!$D$3,IF('امتیاز دهی خبرگان'!$G5=3,'طیف فازی'!$D$4,IF('امتیاز دهی خبرگان'!$G5=4,'طیف فازی'!$D$5,'طیف فازی'!$D$6))))) -> 1 | R5: =IF('امتیاز دهی خبرگان'!$H5=0,0,IF('امتیاز دهی خبرگان'!$H5=1,'طیف فازی'!$B$2,IF('امتیاز دهی خبرگان'!$H5=2,'طیف فازی'!$B$3,IF('امتیاز دهی خبرگان'!$H5=3,'طیف فازی'!$B$4,IF('امتیاز دهی خبرگان'!$H5=4,'طیف فازی'!$B$5,'طیف فازی'!$B$6))))) -> 0.25 | S5: =IF('امتیاز دهی خبرگان'!$H5=0,0,IF('امتیاز دهی خبرگان'!$H5=1,'طیف فازی'!$C$2,IF('امتیاز دهی خبرگان'!$H5=2,'طیف فازی'!$C$3,IF('امتیاز دهی خبرگان'!$H5=3,'طیف فازی'!$C$4,IF('امتیاز دهی خبرگان'!$H5=4,'طیف فازی'!$C$5,'طیف فازی'!$C$6))))) -> 0.5 | T5: =IF('امتیاز دهی خبرگان'!$H5=0,0,IF('امتیاز دهی خبرگان'!$H5=1,'طیف فازی'!$D$2,IF('امتیاز دهی خبرگان'!$H5=2,'طیف فازی'!$D$3,IF('امتیاز دهی خبرگان'!$H5=3,'طیف فازی'!$D$4,IF('امتیاز دهی خبرگان'!$H5=4,'طیف فازی'!$D$5,'طیف فازی'!$D$6))))) -> 0.75 | U5: =IF('امتیاز دهی خبرگان'!$I5=0,0,IF('امتیاز دهی خبرگان'!$I5=1,'طیف فازی'!$B$2,IF('امتیاز دهی خبرگان'!$I5=2,'طیف فازی'!$B$3,IF('امتیاز دهی خبرگان'!$I5=3,'طیف فازی'!$B$4,IF('امتیاز دهی خبرگان'!$I5=4,'طیف فازی'!$B$5,'طیف فازی'!$B$6))))) -> 0.75 | V5: =IF('امتیاز دهی خبرگان'!$I5=0,0,IF('امتیاز دهی خبرگان'!$I5=1,'طیف فازی'!$C$2,IF('امتیاز دهی خبرگان'!$I5=2,'طیف فازی'!$C$3,IF('امتیاز دهی خبرگان'!$I5=3,'طیف فازی'!$C$4,IF('امتیاز دهی خبرگان'!$I5=4,'طیف فازی'!$C$5,'طیف فازی'!$C$6))))) -> 1 | W5: =IF('امتیاز دهی خبرگان'!$I5=0,0,IF('امتیاز دهی خبرگان'!$I5=1,'طیف فازی'!$D$2,IF('امتیاز دهی خبرگان'!$I5=2,'طیف فازی'!$D$3,IF('امتیاز دهی خبرگان'!$I5=3,'طیف فازی'!$D$4,IF('امتیاز دهی خبرگان'!$I5=4,'طیف فازی'!$D$5,'طیف فازی'!$D$6))))) -> 1 | X5: =IF('امتیاز دهی خبرگان'!$J5=0,0,IF('امتیاز دهی خبرگان'!$J5=1,'طیف فازی'!$B$2,IF('امتیاز دهی خبرگان'!$J5=2,'طیف فازی'!$B$3,IF('امتیاز دهی خبرگان'!$J5=3,'طیف فازی'!$B$4,IF('امتیاز دهی خبرگان'!$J5=4,'طیف فازی'!$B$5,'طیف فازی'!$B$6))))) -> 0.75 | Y5: =IF('امتیاز دهی خبرگان'!$J5=0,0,IF('امتیاز دهی خبرگان'!$J5=1,'طیف فازی'!$C$2,IF('امتیاز دهی خبرگان'!$J5=2,'طیف فازی'!$C$3,IF('امتیاز دهی خبرگان'!$J5=3,'طیف فازی'!$C$4,IF('امتیاز دهی خبرگان'!$J5=4,'طیف فازی'!$C$5,'طیف فازی'!$C$6))))) -> 1 | Z5: =IF('امتیاز دهی خبرگان'!$J5=0,0,IF('امتیاز دهی خبرگان'!$J5=1,'طیف فازی'!$D$2,IF('امتیاز دهی خبرگان'!$J5=2,'طیف فازی'!$D$3,IF('امتیاز دهی خبرگان'!$J5=3,'طیف فازی'!$D$4,IF('امتیاز دهی خبرگان'!$J5=4,'طیف فازی'!$D$5,'طیف فازی'!$D$6))))) -> 1 | AA5: =IF('امتیاز دهی خبرگان'!$K5=0,0,IF('امتیاز دهی خبرگان'!$K5=1,'طیف فازی'!$B$2,IF('امتیاز دهی خبرگان'!$K5=2,'طیف فازی'!$B$3,IF('امتیاز دهی خبرگان'!$K5=3,'طیف فازی'!$B$4,IF('امتیاز دهی خبرگان'!$K5=4,'طیف فازی'!$B$5,'طیف فازی'!$B$6))))) -> 0.75 | AB5: =IF('امتیاز دهی خبرگان'!$K5=0,0,IF('امتیاز دهی خبرگان'!$K5=1,'طیف فازی'!$C$2,IF('امتیاز دهی خبرگان'!$K5=2,'طیف فازی'!$C$3,IF('امتیاز دهی خبرگان'!$K5=3,'طیف فازی'!$C$4,IF('امتیاز دهی خبرگان'!$K5=4,'طیف فازی'!$C$5,'طیف فازی'!$C$6))))) -> 1 | AC5: =IF('امتیاز دهی خبرگان'!$K5=0,0,IF('امتیاز دهی خبرگان'!$K5=1,'طیف فازی'!$D$2,IF('امتیاز دهی خبرگان'!$K5=2,'طیف فازی'!$D$3,IF('امتیاز دهی خبرگان'!$K5=3,'طیف فازی'!$D$4,IF('امتیاز دهی خبرگان'!$K5=4,'طیف فازی'!$D$5,'طیف فازی'!$D$6))))) -> 1 | AD5: =IF('امتیاز دهی خبرگان'!$L5=0,0,IF('امتیاز دهی خبرگان'!$L5=1,'طیف فازی'!$B$2,IF('امتیاز دهی خبرگان'!$L5=2,'طیف فازی'!$B$3,IF('امتیاز دهی خبرگان'!$L5=3,'طیف فازی'!$B$4,IF('امتیاز دهی خبرگان'!$L5=4,'طیف فازی'!$B$5,'طیف فازی'!$B$6))))) -> 0.75 | AE5: =IF('امتیاز دهی خبرگان'!$L5=0,0,IF('امتیاز دهی خبرگان'!$L5=1,'طیف فازی'!$C$2,IF('امتیاز دهی خبرگان'!$L5=2,'طیف فازی'!$C$3,IF('امتیاز دهی خبرگان'!$L5=3,'طیف فازی'!$C$4,IF('امتیاز دهی خبرگان'!$L5=4,'طیف فازی'!$C$5,'طیف فازی'!$C$6))))) -> 1 | AF5: =IF('امتیاز دهی خبرگان'!$L5=0,0,IF('امتیاز دهی خبرگان'!$L5=1,'طیف فازی'!$D$2,IF('امتیاز دهی خبرگان'!$L5=2,'طیف فازی'!$D$3,IF('امتیاز دهی خبرگان'!$L5=3,'طیف فازی'!$D$4,IF('امتیاز دهی خبرگان'!$L5=4,'طیف فازی'!$D$5,'طیف فازی'!$D$6))))) -> 1 | AG5: =IF('امتیاز دهی خبرگان'!$M5=0,0,IF('امتیاز دهی خبرگان'!$M5=1,'طیف فازی'!$B$2,IF('امتیاز دهی خبرگان'!$M5=2,'طیف فازی'!$B$3,IF('امتیاز دهی خبرگان'!$M5=3,'طیف فازی'!$B$4,IF('امتیاز دهی خبرگان'!$M5=4,'طیف فازی'!$B$5,'طیف فازی'!$B$6))))) -> 0.75 | AH5: =IF('امتیاز دهی خبرگان'!$M5=0,0,IF('امتیاز دهی خبرگان'!$M5=1,'طیف فازی'!$C$2,IF('امتیاز دهی خبرگان'!$M5=2,'طیف فازی'!$C$3,IF('امتیاز دهی خبرگان'!$M5=3,'طیف فازی'!$C$4,IF('امتیاز دهی خبرگان'!$M5=4,'طیف فازی'!$C$5,'طیف فازی'!$C$6))))) -> 1 | AI5: =IF('امتیاز دهی خبرگان'!$M5=0,0,IF('امتیاز دهی خبرگان'!$M5=1,'طیف فازی'!$D$2,IF('امتیاز دهی خبرگان'!$M5=2,'طیف فازی'!$D$3,IF('امتیاز دهی خبرگان'!$M5=3,'طیف فازی'!$D$4,IF('امتیاز دهی خبرگان'!$M5=4,'طیف فازی'!$D$5,'طیف فازی'!$D$6))))) -> 1 | AJ5: =IF('امتیاز دهی خبرگان'!$N5=0,0,IF('امتیاز دهی خبرگان'!$N5=1,'طیف فازی'!$B$2,IF('امتیاز دهی خبرگان'!$N5=2,'طیف فازی'!$B$3,IF('امتیاز دهی خبرگان'!$N5=3,'طیف فازی'!$B$4,IF('امتیاز دهی خبرگان'!$N5=4,'طیف فازی'!$B$5,'طیف فازی'!$B$6))))) -> 0.75 | AK5: =IF('امتیاز دهی خبرگان'!$N5=0,0,IF('امتیاز دهی خبرگان'!$N5=1,'طیف فازی'!$C$2,IF('امتیاز دهی خبرگان'!$N5=2,'طیف فازی'!$C$3,IF('امتیاز دهی خبرگان'!$N5=3,'طیف فازی'!$C$4,IF('امتیاز دهی خبرگان'!$N5=4,'طیف فازی'!$C$5,'طیف فازی'!$C$6))))) -> 1 | AL5: =IF('امتیاز دهی خبرگان'!$N5=0,0,IF('امتیاز دهی خبرگان'!$N5=1,'طیف فازی'!$D$2,IF('امتیاز دهی خبرگان'!$N5=2,'طیف فازی'!$D$3,IF('امتیاز دهی خبرگان'!$N5=3,'طیف فازی'!$D$4,IF('امتیاز دهی خبرگان'!$N5=4,'طیف فازی'!$D$5,'طیف فازی'!$D$6))))) -> 1 | AM5: =C5+F5+I5+L5+O5+R5+U5+X5+AA5+AD5+AG5+AJ5 -> 7.75 | AN5: =D5+G5+J5+M5+P5+S5+V5+Y5+AB5+AE5+AH5+AK5 -> 10.75 | AO5: =E5+H5+K5+N5+Q5+T5+W5+Z5+AC5+AF5+AI5+AL5 -> 11.5 | AP5: =(AM5)/$AU$4 -> 0.64583333 | AQ5: =(AN5)/$AU$4 -> 0.89583333 | AR5: =(AO5)/$AU$4 -> 0.95833333 | AS5: =AVERAGE(AP5:AR5) -> 0.83333333 | AT5: =IF(AS5>=0.7,"Pass","Not Pass") -> Pass
B6: 4 | C6: =IF('امتیاز دهی خبرگان'!$C6=0,0,IF('امتیاز دهی خبرگان'!$C6=1,'طیف فازی'!$B$2,IF('امتیاز دهی خبرگان'!$C6=2,'طیف فازی'!$B$3,IF('امتیاز دهی خبرگان'!$C6=3,'طیف فازی'!$B$4,IF('امتیاز دهی خبرگان'!$C6=4,'طیف فازی'!$B$5,'طیف فازی'!$B$6))))) -> 0.5 | D6: =IF('امتیاز دهی خبرگان'!$C6=0,0,IF('امتیاز دهی خبرگان'!$C6=1,'طیف فازی'!$C$2,IF('امتیاز دهی خبرگان'!$C6=2,'طیف فازی'!$C$3,IF('امتیاز دهی خبرگان'!$C6=3,'طیف فازی'!$C$4,IF('امتیاز دهی خبرگان'!$C6=4,'طیف فازی'!$C$5,'طیف فازی'!$C$6))))) -> 0.75 | E6: =IF('امتیاز دهی خبرگان'!$C6=0,0,IF('امتیاز دهی خبرگان'!$C6=1,'طیف فازی'!$D$2,IF('امتیاز دهی خبرگان'!$C6=2,'طیف فازی'!$D$3,IF('امتیاز دهی خبرگان'!$C6=3,'طیف فازی'!$D$4,IF('امتیاز دهی خبرگان'!$C6=4,'طیف فازی'!$D$5,'طیف فازی'!$D$6))))) -> 1 | F6: =IF('امتیاز دهی خبرگان'!$D6=0,0,IF('امتیاز دهی خبرگان'!$D6=1,'طیف فازی'!$B$2,IF('امتیاز دهی خبرگان'!$D6=2,'طیف فازی'!$B$3,IF('امتیاز دهی خبرگان'!$D6=3,'طیف فازی'!$B$4,IF('امتیاز دهی خبرگان'!$D6=4,'طیف فازی'!$B$5,'طیف فازی'!$B$6))))) -> 0.5 | G6: =IF('امتیاز دهی خبرگان'!$D6=0,0,IF('امتیاز دهی خبرگان'!$D6=1,'طیف فازی'!$D$2,IF('امتیاز دهی خبرگان'!$D6=2,'طیف فازی'!$C$3,IF('امتیاز دهی خبرگان'!$D6=3,'طیف فازی'!$C$4,IF('امتیاز دهی خبرگان'!$D6=4,'طیف فازی'!$C$5,'طیف فازی'!$C$6))))) -> 0.75 | H6: =IF('امتیاز دهی خبرگان'!$D6=0,0,IF('امتیاز دهی خبرگان'!$D6=1,'طیف فازی'!$D$2,IF('امتیاز دهی خبرگان'!$D6=2,'طیف فازی'!$D$3,IF('امتیاز دهی خبرگان'!$D6=3,'طیف فازی'!$D$4,IF('امتیاز دهی خبرگان'!$D6=4,'طیف فازی'!$D$5,'طیف فازی'!$D$6))))) -> 1 | I6: =IF('امتیاز دهی خبرگان'!$E6=0,0,IF('امتیاز دهی خبرگان'!$E6=1,'طیف فازی'!$B$2,IF('امتیاز دهی خبرگان'!$E6=2,'طیف فازی'!$B$3,IF('امتیاز دهی خبرگان'!$E6=3,'طیف فازی'!$B$4,IF('امتیاز دهی خبرگان'!$E6=4,'طیف فازی'!$B$5,'طیف فازی'!$B$6))))) -> 0.5 | J6: =IF('امتیاز دهی خبرگان'!$E6=0,0,IF('امتیاز دهی خبرگان'!$E6=1,'طیف فازی'!$C$2,IF('امتیاز دهی خبرگان'!$E6=2,'طیف فازی'!$C$3,IF('امتیاز دهی خبرگان'!$E6=3,'طیف فازی'!$C$4,IF('امتیاز دهی خبرگان'!$E6=4,'طیف فازی'!$C$5,'طیف فازی'!$C$6))))) -> 0.75 | K6: =IF('امتیاز دهی خبرگان'!$E6=0,0,IF('امتیاز دهی خبرگان'!$E6=1,'طیف فازی'!$D$2,IF('امتیاز دهی خبرگان'!$E6=2,'طیف فازی'!$D$3,IF('امتیاز دهی خبرگان'!$E6=3,'طیف فازی'!$D$4,IF('امتیاز دهی خبرگان'!$E6=4,'طیف فازی'!$D$5,'طیف فازی'!$D$6))))) -> 1 | L6: =IF('امتیاز دهی خبرگان'!$F6=0,0,IF('امتیاز دهی خبرگان'!$F6=1,'طیف فازی'!$B$2,IF('امتیاز دهی خبرگان'!$F6=2,'طیف فازی'!$B$3,IF('امتیاز دهی خبرگان'!$F6=3,'طیف فازی'!$B$4,IF('امتیاز دهی خبرگان'!$F6=4,'طیف فازی'!$B$5,'طیف فازی'!$B$6))))) -> 0.25 | M6: =IF('امتیاز دهی خبرگان'!$F6=0,0,IF('امتیاز دهی خبرگان'!$F6=1,'طیف فازی'!$C$2,IF('امتیاز دهی خبرگان'!$F6=2,'طیف فازی'!$C$3,IF('امتیاز دهی خبرگان'!$F6=3,'طیف فازی'!$C$4,IF('امتیاز دهی خبرگان'!$F6=4,'طیف فازی'!$C$5,'طیف فازی'!$C$6))))) -> 0.5 | N6: =IF('امتیاز دهی خبرگان'!$F6=0,0,IF('امتیاز دهی خبرگان'!$F6=1,'طیف فازی'!$D$2,IF('امتیاز دهی خبرگان'!$F6=2,'طیف فازی'!$D$3,IF('امتیاز دهی خبرگان'!$F6=3,'طیف فازی'!$D$4,IF('امتیاز دهی خبرگان'!$F6=4,'طیف فازی'!$D$5,'طیف فازی'!$D$6))))) -> 0.75 | O6: =IF('امتیاز دهی خبرگان'!$G6=0,0,IF('امتیاز دهی خبرگان'!$G6=1,'طیف فازی'!$B$2,IF('امتیاز دهی خبرگان'!$G6=2,'طیف فازی'!$B$3,IF('امتیاز دهی خبرگان'!$G6=3,'طیف فازی'!$B$4,IF('امتیاز دهی خبرگان'!$G6=4,'طیف فازی'!$B$5,'طیف فازی'!$B$6))))) -> 0.5 | P6: =IF('امتیاز دهی خبرگان'!$G6=0,0,IF('امتیاز دهی خبرگان'!$G6=1,'طیف فازی'!$C$2,IF('امتیاز دهی خبرگان'!$G6=2,'طیف فازی'!$C$3,IF('امتیاز دهی خبرگان'!$G6=3,'طیف فازی'!$C$4,IF('امتیاز دهی خبرگان'!$G6=4,'طیف فازی'!$C$5,'طیف فازی'!$C$6))))) -> 0.75 | Q6: =IF('امتیاز دهی خبرگان'!$G6=0,0,IF('امتیاز دهی خبرگان'!$G6=1,'طیف فازی'!$D$2,IF('امتیاز دهی خبرگان'!$G6=2,'طیف فازی'!$D$3,IF('امتیاز دهی خبرگان'!$G6=3,'طیف فازی'!$D$4,IF('امتیاز دهی خبرگان'!$G6=4,'طیف فازی'!$D$5,'طیف فازی'!$D$6))))) -> 1 | R6: =IF('امتیاز دهی خبرگان'!$H6=0,0,IF('امتیاز دهی خبرگان'!$H6=1,'طیف فازی'!$B$2,IF('امتیاز دهی خبرگان'!$H6=2,'طیف فازی'!$B$3,IF('امتیاز دهی خبرگان'!$H6=3,'طیف فازی'!$B$4,IF('امتیاز دهی خبرگان'!$H6=4,'طیف فازی'!$B$5,'طیف فازی'!$B$6))))) -> 0.75 | S6: =IF('امتیاز دهی خبرگان'!$H6=0,0,IF('امتیاز دهی خبرگان'!$H6=1,'طیف فازی'!$C$2,IF('امتیاز دهی خبرگان'!$H6=2,'طیف فازی'!$C$3,IF('امتیاز دهی خبرگان'!$H6=3,'طیف فازی'!$C$4,IF('امتیاز دهی خبرگان'!$H6=4,'طیف فازی'!$C$5,'طیف فازی'!$C$6))))) -> 1 | T6: =IF('امتیاز دهی خبرگان'!$H6=0,0,IF('امتیاز دهی خبرگان'!$H6=1,'طیف فازی'!$D$2,IF('امتیاز دهی خبرگان'!$H6=2,'طیف فازی'!$D$3,IF('امتیاز دهی خبرگان'!$H6=3,'طیف فازی'!$D$4,IF('امتیاز دهی خبرگان'!$H6=4,'طیف فازی'!$D$5,'طیف فازی'!$D$6))))) -> 1 | U6: =IF('امتیاز دهی خبرگان'!$I6=0,0,IF('امتیاز دهی خبرگان'!$I6=1,'طیف فازی'!$B$2,IF('امتیاز دهی خبرگان'!$I6=2,'طیف فازی'!$B$3,IF('امتیاز دهی خبرگان'!$I6=3,'طیف فازی'!$B$4,IF('امتیاز دهی خبرگان'!$I6=4,'طیف فازی'!$B$5,'طیف فازی'!$B$6))))) -> 0.25 | V6: =IF('امتیاز دهی خبرگان'!$I6=0,0,IF('امتیاز دهی خبرگان'!$I6=1,'طیف فازی'!$C$2,IF('امتیاز دهی خبرگان'!$I6=2,'طیف فازی'!$C$3,IF('امتیاز دهی خبرگان'!$I6=3,'طیف فازی'!$C$4,IF('امتیاز دهی خبرگان'!$I6=4,'طیف فازی'!$C$5,'طیف فازی'!$C$6))))) -> 0.5 | W6: =IF('امتیاز دهی خبرگان'!$I6=0,0,IF('امتیاز دهی خبرگان'!$I6=1,'طیف فازی'!$D$2,IF('امتیاز دهی خبرگان'!$I6=2,'طیف فازی'!$D$3,IF('امتیاز دهی خبرگان'!$I6=3,'طیف فازی'!$D$4,IF('امتیاز دهی خبرگان'!$I6=4,'طیف فازی'!$D$5,'طیف فازی'!$D$6))))) -> 0.75 | X6: =IF('امتیاز دهی خبرگان'!$J6=0,0,IF('امتیاز دهی خبرگان'!$J6=1,'طیف فازی'!$B$2,IF('امتیاز دهی خبرگان'!$J6=2,'طیف فازی'!$B$3,IF('امتیاز دهی خبرگان'!$J6=3,'طیف فازی'!$B$4,IF('امتیاز دهی خبرگان'!$J6=4,'طیف فازی'!$B$5,'طیف فازی'!$B$6))))) -> 0.5 | Y6: =IF('امتیاز دهی خبرگان'!$J6=0,0,IF('امتیاز دهی خبرگان'!$J6=1,'طیف فازی'!$C$2,IF('امتیاز دهی خبرگان'!$J6=2,'طیف فازی'!$C$3,IF('امتیاز دهی خبرگان'!$J6=3,'طیف فازی'!$C$4,IF('امتیاز دهی خبرگان'!$J6=4,'طیف فازی'!$C$5,'طیف فازی'!$C$6))))) -> 0.75 | Z6: =IF('امتیاز دهی خبرگان'!$J6=0,0,IF('امتیاز دهی خبرگان'!$J6=1,'طیف فازی'!$D$2,IF('امتیاز دهی خبرگان'!$J6=2,'طیف فازی'!$D$3,IF('امتیاز دهی خبرگان'!$J6=3,'طیف فازی'!$D$4,IF('امتیاز دهی خبرگان'!$J6=4,'طیف فازی'!$D$5,'طیف فازی'!$D$6))))) -> 1 | AA6: =IF('امتیاز دهی خبرگان'!$K6=0,0,IF('امتیاز دهی خبرگان'!$K6=1,'طیف فازی'!$B$2,IF('امتیاز دهی خبرگان'!$K6=2,'طیف فازی'!$B$3,IF('امتیاز دهی خبرگان'!$K6=3,'طیف فازی'!$B$4,IF('امتیاز دهی خبرگان'!$K6=4,'طیف فازی'!$B$5,'طیف فازی'!$B$6))))) -> 0.75 | AB6: =IF('امتیاز دهی خبرگان'!$K6=0,0,IF('امتیاز دهی خبرگان'!$K6=1,'طیف فازی'!$C$2,IF('امتیاز دهی خبرگان'!$K6=2,'طیف فازی'!$C$3,IF('امتیاز دهی خبرگان'!$K6=3,'طیف فازی'!$C$4,IF('امتیاز دهی خبرگان'!$K6=4,'طیف فازی'!$C$5,'طیف فازی'!$C$6))))) -> 1 | AC6: =IF('امتیاز دهی خبرگان'!$K6=0,0,IF('امتیاز دهی خبرگان'!$K6=1,'طیف فازی'!$D$2,IF('امتیاز دهی خبرگان'!$K6=2,'طیف فازی'!$D$3,IF('امتیاز دهی خبرگان'!$K6=3,'طیف فازی'!$D$4,IF('امتیاز دهی خبرگان'!$K6=4,'طیف فازی'!$D$5,'طیف فازی'!$D$6))))) -> 1 | AD6: =IF('امتیاز دهی خبرگان'!$L6=0,0,IF('امتیاز دهی خبرگان'!$L6=1,'طیف فازی'!$B$2,IF('امتیاز دهی خبرگان'!$L6=2,'طیف فازی'!$B$3,IF('امتیاز دهی خبرگان'!$L6=3,'طیف فازی'!$B$4,IF('امتیاز دهی خبرگان'!$L6=4,'طیف فازی'!$B$5,'طیف فازی'!$B$6))))) -> 0.75 | AE6: =IF('امتیاز دهی خبرگان'!$L6=0,0,IF('امتیاز دهی خبرگان'!$L6=1,'طیف فازی'!$C$2,IF('امتیاز دهی خبرگان'!$L6=2,'طیف فازی'!$C$3,IF('امتیاز دهی خبرگان'!$L6=3,'طیف فازی'!$C$4,IF('امتیاز دهی خبرگان'!$L6=4,'طیف فازی'!$C$5,'طیف فازی'!$C$6))))) -> 1 | AF6: =IF('امتیاز دهی خبرگان'!$L6=0,0,IF('امتیاز دهی خبرگان'!$L6=1,'طیف فازی'!$D$2,IF('امتیاز دهی خبرگان'!$L6=2,'طیف فازی'!$D$3,IF('امتیاز دهی خبرگان'!$L6=3,'طیف فازی'!$D$4,IF('امتیاز دهی خبرگان'!$L6=4,'طیف فازی'!$D$5,'طیف فازی'!$D$6))))) -> 1 | AG6: =IF('امتیاز دهی خبرگان'!$M6=0,0,IF('امتیاز دهی خبرگان'!$M6=1,'طیف فازی'!$B$2,IF('امتیاز دهی خبرگان'!$M6=2,'طیف فازی'!$B$3,IF('امتیاز دهی خبرگان'!$M6=3,'طیف فازی'!$B$4,IF('امتیاز دهی خبرگان'!$M6=4,'طیف فازی'!$B$5,'طیف فازی'!$B$6))))) -> 0.5 | AH6: =IF('امتیاز دهی خبرگان'!$M6=0,0,IF('امتیاز دهی خبرگان'!$M6=1,'طیف فازی'!$C$2,IF('امتیاز دهی خبرگان'!$M6=2,'طیف فازی'!$C$3,IF('امتیاز دهی خبرگان'!$M6=3,'طیف فازی'!$C$4,IF('امتیاز دهی خبرگان'!$M6=4,'طیف فازی'!$C$5,'طیف فازی'!$C$6))))) -> 0.75 | AI6: =IF('امتیاز دهی خبرگان'!$M6=0,0,IF('امتیاز دهی خبرگان'!$M6=1,'طیف فازی'!$D$2,IF('امتیاز دهی خبرگان'!$M6=2,'طیف فازی'!$D$3,IF('امتیاز دهی خبرگان'!$M6=3,'طیف فازی'!$D$4,IF('امتیاز دهی خبرگان'!$M6=4,'طیف فازی'!$D$5,'طیف فازی'!$D$6))))) -> 1 | AJ6: =IF('امتیاز دهی خبرگان'!$N6=0,0,IF('امتیاز دهی خبرگان'!$N6=1,'طیف فازی'!$B$2,IF('امتیاز دهی خبرگان'!$N6=2,'طیف فازی'!$B$3,IF('امتیاز دهی خبرگان'!$N6=3,'طیف فازی'!$B$4,IF('امتیاز دهی خبرگان'!$N6=4,'طیف فازی'!$B$5,'طیف فازی'!$B$6))))) -> 0.5 | AK6: =IF('امتیاز دهی خبرگان'!$N6=0,0,IF('امتیاز دهی خبرگان'!$N6=1,'طیف فازی'!$C$2,IF('امتیاز دهی خبرگان'!$N6=2,'طیف فازی'!$C$3,IF('امتیاز دهی خبرگان'!$N6=3,'طیف فازی'!$C$4,IF('امتیاز دهی خبرگان'!$N6=4,'طیف فازی'!$C$5,'طیف فازی'!$C$6))))) -> 0.75 | AL6: =IF('امتیاز دهی خبرگان'!$N6=0,0,IF('امتیاز دهی خبرگان'!$N6=1,'طیف فازی'!$D$2,IF('امتیاز دهی خبرگان'!$N6=2,'طیف فازی'!$D$3,IF('امتیاز دهی خبرگان'!$N6=3,'طیف فازی'!$D$4,IF('امتیاز دهی خبرگان'!$N6=4,'طیف فازی'!$D$5,'طیف فازی'!$D$6))))) -> 1 | AM6: =C6+F6+I6+L6+O6+R6+U6+X6+AA6+AD6+AG6+AJ6 -> 6.25 | AN6: =D6+G6+J6+M6+P6+S6+V6+Y6+AB6+AE6+AH6+AK6 -> 9.25 | AO6: =E6+H6+K6+N6+Q6+T6+W6+Z6+AC6+AF6+AI6+AL6 -> 11.5 | AP6: =(AM6)/$AU$4 -> 0.52083333 | AQ6: =(AN6)/$AU$4 -> 0.77083333 | AR6: =(AO6)/$AU$4 -> 0.95833333 | AS6: =AVERAGE(AP6:AR6) -> 0.75 | AT6: =IF(AS6>=0.7,"Pass","Not Pass") -> Pass
B7: 5 | C7: =IF('امتیاز دهی خبرگان'!$C7=0,0,IF('امتیاز دهی خبرگان'!$C7=1,'طیف فازی'!$B$2,IF('امتیاز دهی خبرگان'!$C7=2,'طیف فازی'!$B$3,IF('امتیاز دهی خبرگان'!$C7=3,'طیف فازی'!$B$4,IF('امتیاز دهی خبرگان'!$C7=4,'طیف فازی'!$B$5,'طیف فازی'!$B$6))))) -> 0.75 | D7: =IF('امتیاز دهی خبرگان'!$C7=0,0,IF('امتیاز دهی خبرگان'!$C7=1,'طیف فازی'!$C$2,IF('امتیاز دهی خبرگان'!$C7=2,'طیف فازی'!$C$3,IF('امتیاز دهی خبرگان'!$C7=3,'طیف فازی'!$C$4,IF('امتیاز دهی خبرگان'!$C7=4,'طیف فازی'!$C$5,'طیف فازی'!$C$6))))) -> 1 | E7: =IF('امتیاز دهی خبرگان'!$C7=0,0,IF('امتیاز دهی خبرگان'!$C7=1,'طیف فازی'!$D$2,IF('امتیاز دهی خبرگان'!$C7=2,'طیف فازی'!$D$3,IF('امتیاز دهی خبرگان'!$C7=3,'طیف فازی'!$D$4,IF('امتیاز دهی خبرگان'!$C7=4,'طیف فازی'!$D$5,'طیف فازی'!$D$6))))) -> 1 | F7: =IF('امتیاز دهی خبرگان'!$D7=0,0,IF('امتیاز دهی خبرگان'!$D7=1,'طیف فازی'!$B$2,IF('امتیاز دهی خبرگان'!$D7=2,'طیف فازی'!$B$3,IF('امتیاز دهی خبرگان'!$D7=3,'طیف فازی'!$B$4,IF('امتیاز دهی خبرگان'!$D7=4,'طیف فازی'!$B$5,'طیف فازی'!$B$6))))) -> 0 | G7: =IF('امتیاز دهی خبرگان'!$D7=0,0,IF('امتیاز دهی خبرگان'!$D7=1,'طیف فازی'!$D$2,IF('امتیاز دهی خبرگان'!$D7=2,'طیف فازی'!$C$3,IF('امتیاز دهی خبرگان'!$D7=3,'طیف فازی'!$C$4,IF('امتیاز دهی خبرگان'!$D7=4,'طیف فازی'!$C$5,'طیف فازی'!$C$6))))) -> 0.25 | H7: =IF('امتیاز دهی خبرگان'!$D7=0,0,IF('امتیاز دهی خبرگان'!$D7=1,'طیف فازی'!$D$2,IF('امتیاز دهی خبرگان'!$D7=2,'طیف فازی'!$D$3,IF('امتیاز دهی خبرگان'!$D7=3,'طیف فازی'!$D$4,IF('امتیاز دهی خبرگان'!$D7=4,'طیف فازی'!$D$5,'طیف فازی'!$D$6))))) -> 0.5 | I7: =IF('امتیاز دهی خبرگان'!$E7=0,0,IF('امتیاز دهی خبرگان'!$E7=1,'طیف فازی'!$B$2,IF('امتیاز دهی خبرگان'!$E7=2,'طیف فازی'!$B$3,IF('امتیاز دهی خبرگان'!$E7=3,'طیف فازی'!$B$4,IF('امتیاز دهی خبرگان'!$E7=4,'طیف فازی'!$B$5,'طیف فازی'!$B$6))))) -> 0.25 | J7: =IF('امتیاز دهی خبرگان'!$E7=0,0,IF('امتیاز دهی خبرگان'!$E7=1,'طیف فازی'!$C$2,IF('امتیاز دهی خبرگان'!$E7=2,'طیف فازی'!$C$3,IF('امتیاز دهی خبرگان'!$E7=3,'طیف فازی'!$C$4,IF('امتیاز دهی خبرگان'!$E7=4,'طیف فازی'!$C$5,'طیف فازی'!$C$6))))) -> 0.5 | K7: =IF('امتیاز دهی خبرگان'!$E7=0,0,IF('امتیاز دهی خبرگان'!$E7=1,'طیف فازی'!$D$2,IF('امتیاز دهی خبرگان'!$E7=2,'طیف فازی'!$D$3,IF('امتیاز دهی خبرگان'!$E7=3,'طیف فازی'!$D$4,IF('امتیاز دهی خبرگان'!$E7=4,'طیف فازی'!$D$5,'طیف فازی'!$D$6))))) -> 0.75 | L7: =IF('امتیاز دهی خبرگان'!$F7=0,0,IF('امتیاز دهی خبرگان'!$F7=1,'طیف فازی'!$B$2,IF('امتیاز دهی خبرگان'!$F7=2,'طیف فازی'!$B$3,IF('امتیاز دهی خبرگان'!$F7=3,'طیف فازی'!$B$4,IF('امتیاز دهی خبرگان'!$F7=4,'طیف فازی'!$B$5,'طیف فازی'!$B$6))))) -> 0.75 | M7: =IF('امتیاز دهی خبرگان'!$F7=0,0,IF('امتیاز دهی خبرگان'!$F7=1,'طیف فازی'!$C$2,IF('امتیاز دهی خبرگان'!$F7=2,'طیف فازی'!$C$3,IF('امتیاز دهی خبرگان'!$F7=3,'طیف فازی'!$C$4,IF('امتیاز دهی خبرگان'!$F7=4,'طیف فازی'!$C$5,'طیف فازی'!$C$6))))) -> 1 | N7: =IF('امتیاز دهی خبرگان'!$F7=0,0,IF('امتیاز دهی خبرگان'!$F7=1,'طیف فازی'!$D$2,IF('امتیاز دهی خبرگان'!$F7=2,'طیف فازی'!$D$3,IF('امتیاز دهی خبرگان'!$F7=3,'طیف فازی'!$D$4,IF('امتیاز دهی خبرگان'!$F7=4,'طیف فازی'!$D$5,'طیف فازی'!$D$6))))) -> 1 | O7: =IF('امتیاز دهی خبرگان'!$G7=0,0,IF('امتیاز دهی خبرگان'!$G7=1,'طیف فازی'!$B$2,IF('امتیاز دهی خبرگان'!$G7=2,'طیف فازی'!$B$3,IF('امتیاز دهی خبرگان'!$G7=3,'طیف فازی'!$B$4,IF('امتیاز دهی خبرگان'!$G7=4,'طیف فازی'!$B$5,'طیف فازی'!$B$6))))) -> 0.75 | P7: =IF('امتیاز دهی خبرگان'!$G7=0,0,IF('امتیاز دهی خبرگان'!$G7=1,'طیف فازی'!$C$2,IF('امتیاز دهی خبرگان'!$G7=2,'طیف فازی'!$C$3,IF('امتیاز دهی خبرگان'!$G7=3,'طیف فازی'!$C$4,IF('امتیاز دهی خبرگان'!$G7=4,'طیف فازی'!$C$5,'طیف فازی'!$C$6))))) -> 1 | Q7: =IF('امتیاز دهی خبرگان'!$G7=0,0,IF('امتیاز دهی خبرگان'!$G7=1,'طیف فازی'!$D$2,IF('امتیاز دهی خبرگان'!$G7=2,'طیف فازی'!$D$3,IF('امتیاز دهی خبرگان'!$G7=3,'طیف فازی'!$D$4,IF('امتیاز دهی خبرگان'!$G7=4,'طیف فازی'!$D$5,'طیف فازی'!$D$6))))) -> 1 | R7: =IF('امتیاز دهی خبرگان'!$H7=0,0,IF('امتیاز دهی خبرگان'!$H7=1,'طیف فازی'!$B$2,IF('امتیاز دهی خبرگان'!$H7=2,'طیف فازی'!$B$3,IF('امتیاز دهی خبرگان'!$H7=3,'طیف فازی'!$B$4,IF('امتیاز دهی خبرگان'!$H7=4,'طیف فازی'!$B$5,'طیف فازی'!$B$6))))) -> 0.5 | S7: =IF('امتیاز دهی خبرگان'!$H7=0,0,IF('امتیاز دهی خبرگان'!$H7=1,'طیف فازی'!$C$2,IF('امتیاز دهی خبرگان'!$H7=2,'طیف فازی'!$C$3,IF('امتیاز دهی خبرگان'!$H7=3,'طیف فازی'!$C$4,IF('امتیاز دهی خبرگان'!$H7=4,'طیف فازی'!$C$5,'طیف فازی'!$C$6))))) -> 0.75 | T7: =IF('امتیاز دهی خبرگان'!$H7=0,0,IF('امتیاز دهی خبرگان'!$H7=1,'طیف فازی'!$D$2,IF('امتیاز دهی خبرگان'!$H7=2,'طیف فازی'!$D$3,IF('امتیاز دهی خبرگان'!$H7=3,'طیف فازی'!$D$4,IF('امتیاز دهی خبرگان'!$H7=4,'طیف فازی'!$D$5,'طیف فازی'!$D$6))))) -> 1 | U7: =IF('امتیاز دهی خبرگان'!$I7=0,0,IF('امتیاز دهی خبرگان'!$I7=1,'طیف فازی'!$B$2,IF('امتیاز دهی خبرگان'!$I7=2,'طیف فازی'!$B$3,IF('امتیاز دهی خبرگان'!$I7=3,'طیف فازی'!$B$4,IF('امتیاز دهی خبرگان'!$I7=4,'طیف فازی'!$B$5,'طیف فازی'!$B$6))))) -> 0.75 | V7: =IF('امتیاز دهی خبرگان'!$I7=0,0,IF('امتیاز دهی خبرگان'!$I7=1,'طیف فازی'!$C$2,IF('امتیاز دهی خبرگان'!$I7=2,'طیف فازی'!$C$3,IF('امتیاز دهی خبرگان'!$I7=3,'طیف فازی'!$C$4,IF('امتیاز دهی خبرگان'!$I7=4,'طیف فازی'!$C$5,'طیف فازی'!$C$6))))) -> 1 | W7: =IF('امتیاز دهی خبرگان'!$I7=0,0,IF('امتیاز دهی خبرگان'!$I7=1,'طیف فازی'!$D$2,IF('امتیاز دهی خبرگان'!$I7=2,'طیف فازی'!$D$3,IF('امتیاز دهی خبرگان'!$I7=3,'طیف فازی'!$D$4,IF('امتیاز دهی خبرگان'!$I7=4,'طیف فازی'!$D$5,'طیف فازی'!$D$6))))) -> 1 | X7: =IF('امتیاز دهی خبرگان'!$J7=0,0,IF('امتیاز دهی خبرگان'!$J7=1,'طیف فازی'!$B$2,IF('امتیاز دهی خبرگان'!$J7=2,'طیف فازی'!$B$3,IF('امتیاز دهی خبرگان'!$J7=3,'طیف فازی'!$B$4,IF('امتیاز دهی خبرگان'!$J7=4,'طیف فازی'!$B$5,'طیف فازی'!$B$6))))) -> 0.5 | Y7: =IF('امتیاز دهی خبرگان'!$J7=0,0,IF('امتیاز دهی خبرگان'!$J7=1,'طیف فازی'!$C$2,IF('امتیاز دهی خبرگان'!$J7=2,'طیف فازی'!$C$3,IF('امتیاز دهی خبرگان'!$J7=3,'طیف فازی'!$C$4,IF('امتیاز دهی خبرگان'!$J7=4,'طیف فازی'!$C$5,'طیف فازی'!$C$6))))) -> 0.75 | Z7: =IF('امتیاز دهی خبرگان'!$J7=0,0,IF('امتیاز دهی خبرگان'!$J7=1,'طیف فازی'!$D$2,IF('امتیاز دهی خبرگان'!$J7=2,'طیف فازی'!$D$3,IF('امتیاز دهی خبرگان'!$J7=3,'طیف فازی'!$D$4,IF('امتیاز دهی خبرگان'!$J7=4,'طیف فازی'!$D$5,'طیف فازی'!$D$6))))) -> 1 | AA7: =IF('امتیاز دهی خبرگان'!$K7=0,0,IF('امتیاز دهی خبرگان'!$K7=1,'طیف فازی'!$B$2,IF('امتیاز دهی خبرگان'!$K7=2,'طیف فازی'!$B$3,IF('امتیاز دهی خبرگان'!$K7=3,'طیف فازی'!$B$4,IF('امتیاز دهی خبرگان'!$K7=4,'طیف فازی'!$B$5,'طیف فازی'!$B$6))))) -> 0.5 | AB7: =IF('امتیاز دهی خبرگان'!$K7=0,0,IF('امتیاز دهی خبرگان'!$K7=1,'طیف فازی'!$C$2,IF('امتیاز دهی خبرگان'!$K7=2,'طیف فازی'!$C$3,IF('امتیاز دهی خبرگان'!$K7=3,'طیف فازی'!$C$4,IF('امتیاز دهی خبرگان'!$K7=4,'طیف فازی'!$C$5,'طیف فازی'!$C$6))))) -> 0.75 | AC7: =IF('امتیاز دهی خبرگان'!$K7=0,0,IF('امتیاز دهی خبرگان'!$K7=1,'طیف فازی'!$D$2,IF('امتیاز دهی خبرگان'!$K7=2,'طیف فازی'!$D$3,IF('امتیاز دهی خبرگان'!$K7=3,'طیف فازی'!$D$4,IF('امتیاز دهی خبرگان'!$K7=4,'طیف فازی'!$D$5,'طیف فازی'!$D$6))))) -> 1 | AD7: =IF('امتیاز دهی خبرگان'!$L7=0,0,IF('امتیاز دهی خبرگان'!$L7=1,'طیف فازی'!$B$2,IF('امتیاز دهی خبرگان'!$L7=2,'طیف فازی'!$B$3,IF('امتیاز دهی خبرگان'!$L7=3,'طیف فازی'!$B$4,IF('امتیاز دهی خبرگان'!$L7=4,'طیف فازی'!$B$5,'طیف فازی'!$B$6))))) -> 0.5 | AE7: =IF('امتیاز دهی خبرگان'!$L7=0,0,IF('امتیاز دهی خبرگان'!$L7=1,'طیف فازی'!$C$2,IF('امتیاز دهی خبرگان'!$L7=2,'طیف فازی'!$C$3,IF('امتیاز دهی خبرگان'!$L7=3,'طیف فازی'!$C$4,IF('امتیاز دهی خبرگان'!$L7=4,'طیف فازی'!$C$5,'طیف فازی'!$C$6))))) -> 0.75 | AF7: =IF('امتیاز دهی خبرگان'!$L7=0,0,IF('امتیاز دهی خبرگان'!$L7=1,'طیف فازی'!$D$2,IF('امتیاز دهی خبرگان'!$L7=2,'طیف فازی'!$D$3,IF('امتیاز دهی خبرگان'!$L7=3,'طیف فازی'!$D$4,IF('امتیاز دهی خبرگان'!$L7=4,'طیف فازی'!$D$5,'طیف فازی'!$D$6))))) -> 1 | AG7: =IF('امتیاز دهی خبرگان'!$M7=0,0,IF('امتیاز دهی خبرگان'!$M7=1,'طیف فازی'!$B$2,IF('امتیاز دهی خبرگان'!$M7=2,'طیف فازی'!$B$3,IF('امتیاز دهی خبرگان'!$M7=3,'طیف فازی'!$B$4,IF('امتیاز دهی خبرگان'!$M7=4,'طیف فازی'!$B$5,'طیف فازی'!$B$6))))) -> 0.5 | AH7: =IF('امتیاز دهی خبرگان'!$M7=0,0,IF('امتیاز دهی خبرگان'!$M7=1,'طیف فازی'!$C$2,IF('امتیاز دهی خبرگان'!$M7=2,'طیف فازی'!$C$3,IF('امتیاز دهی خبرگان'!$M7=3,'طیف فازی'!$C$4,IF('امتیاز دهی خبرگان'!$M7=4,'طیف فازی'!$C$5,'طیف فازی'!$C$6))))) -> 0.75 | AI7: =IF('امتیاز دهی خبرگان'!$M7=0,0,IF('امتیاز دهی خبرگان'!$M7=1,'طیف فازی'!$D$2,IF('امتیاز دهی خبرگان'!$M7=2,'طیف فازی'!$D$3,IF('امتیاز دهی خبرگان'!$M7=3,'طیف فازی'!$D$4,IF('امتیاز دهی خبرگان'!$M7=4,'طیف فازی'!$D$5,'طیف فازی'!$D$6))))) -> 1 | AJ7: =IF('امتیاز دهی خبرگان'!$N7=0,0,IF('امتیاز دهی خبرگان'!$N7=1,'طیف فازی'!$B$2,IF('امتیاز دهی خبرگان'!$N7=2,'طیف فازی'!$B$3,IF('امتیاز دهی خبرگان'!$N7=3,'طیف فازی'!$B$4,IF('امتیاز دهی خبرگان'!$N7=4,'طیف فازی'!$B$5,'طیف فازی'!$B$6))))) -> 0.75 | AK7: =IF('امتیاز دهی خبرگان'!$N7=0,0,IF('امتیاز دهی خبرگان'!$N7=1,'طیف فازی'!$C$2,IF('امتیاز دهی خبرگان'!$N7=2,'طیف فازی'!$C$3,IF('امتیاز دهی خبرگان'!$N7=3,'طیف فازی'!$C$4,IF('امتیاز دهی خبرگان'!$N7=4,'طیف فازی'!$C$5,'طیف فازی'!$C$6))))) -> 1 | AL7: =IF('امتیاز دهی خبرگان'!$N7=0,0,IF('امتیاز دهی خبرگان'!$N7=1,'طیف فازی'!$D$2,IF('امتیاز دهی خبرگان'!$N7=2,'طیف فازی'!$D$3,IF('امتیاز دهی خبرگان'!$N7=3,'طیف فازی'!$D$4,IF('امتیاز دهی خبرگان'!$N7=4,'طیف فازی'!$D$5,'طیف فازی'!$D$6))))) -> 1 | AM7: =C7+F7+I7+L7+O7+R7+U7+X7+AA7+AD7+AG7+AJ7 -> 6.5 | AN7: =D7+G7+J7+M7+P7+S7+V7+Y7+AB7+AE7+AH7+AK7 -> 9.5 | AO7: =E7+H7+K7+N7+Q7+T7+W7+Z7+AC7+AF7+AI7+AL7 -> 11.25 | AP7: =(AM7)/$AU$4 -> 0.54166667 | AQ7: =(AN7)/$AU$4 -> 0.79166667 | AR7: =(AO7)/$AU$4 -> 0.9375 | AS7: =AVERAGE(AP7:AR7) -> 0.75694444 | AT7: =IF(AS7>=0.7,"Pass","Not Pass") -> Pass
